Workbook

Sheet DASHBOARD
B2: DASHBOARD DE CANTIDADES RCI – UNIQUE 76
B3: Todo se recalcula desde BD_REVIT. Cambie el código en la celda amarilla para ver otro ítem.
B5: Elementos Revit | C5: Asignados | D5: Sin asignar | E5: % asignado | G5: Ítems cap. 7 con cantidad | H5: Niveles con elementos
B6: =COUNTA(BD_REVIT!$A$6:$A$466) -> 461 | C6: =COUNTIF(BD_REVIT!$M$6:$M$466,"ASIGNADO") -> 461 | D6: =COUNTIF(BD_REVIT!$M$6:$M$466,"SIN ASIGNAR") -> 0 | E6: =IFERROR(C6/B6,0) -> 1 | G6: =COUNTIF('CRUCE RCI'!Z6:Z122,">0") -> 65 | H6: =SUMPRODUCT(--(COUNTIF(BD_REVIT!$F$6:$F$466,LISTAS!$D$2:$D$22)>0)) -> 21
B9: ÍTEM SELECCIONADO | G9: RESUMEN POR CATEGORÍA
B10: Código | C10: 7.08 | G10: Categoría | H10: Elementos | I10: Asignados | J10: Sin asignar
B11: Descripción | C11: =IFERROR(INDEX(LISTAS!$B:$B,MATCH($C$10,LISTAS!$A:$A,0)),"") -> Tubería A.C. Sche 10 De ø1 1/2" | G11: Accesorios | H11: =COUNTIF(BD_REVIT!$B$6:$B$466,G11) -> 33 | I11: =COUNTIFS(BD_REVIT!$B$6:$B$466,G11,BD_REVIT!$M$6:$M$466,"ASIGNADO") -> 33 | J11: =H11-I11 -> 0
B12: Unidad | C12: =IFERROR(INDEX(LISTAS!$C:$C,MATCH($C$10,LISTAS!$A:$A,0)),"") -> Ml. | G12: Equipos | H12: =COUNTIF(BD_REVIT!$B$6:$B$466,G12) -> 3 | I12: =COUNTIFS(BD_REVIT!$B$6:$B$466,G12,BD_REVIT!$M$6:$M$466,"ASIGNADO") -> 3 | J12: =H12-I12 -> 0
B13: Cantidad global | C13: =SUMIFS(BD_REVIT!$H:$H,BD_REVIT!$C:$C,$C$10) -> 945.16 | G13: Rociadores | H13: =COUNTIF(BD_REVIT!$B$6:$B$466,G13) -> 6 | I13: =COUNTIFS(BD_REVIT!$B$6:$B$466,G13,BD_REVIT!$M$6:$M$466,"ASIGNADO") -> 6 | J13: =H13-I13 -> 0
B14: Elementos Revit | C14: =COUNTIF(BD_REVIT!$C:$C,$C$10) -> 40 | G14: Soportes | H14: =COUNTIF(BD_REVIT!$B$6:$B$466,G14) -> 53 | I14: =COUNTIFS(BD_REVIT!$B$6:$B$466,G14,BD_REVIT!$M$6:$M$466,"ASIGNADO") -> 53 | J14: =H14-I14 -> 0
G15: Tuberías | H15: =COUNTIF(BD_REVIT!$B$6:$B$466,G15) -> 94 | I15: =COUNTIFS(BD_REVIT!$B$6:$B$466,G15,BD_REVIT!$M$6:$M$466,"ASIGNADO") -> 94 | J15: =H15-I15 -> 0
B16: Nivel de piso | C16: Cantidad ítem | D16: Elementos (todos) | G16: Uniones | H16: =COUNTIF(BD_REVIT!$B$6:$B$466,G16) -> 272 | I16: =COUNTIFS(BD_REVIT!$B$6:$B$466,G16,BD_REVIT!$M$6:$M$466,"ASIGNADO") -> 272 | J16: =H16-I16 -> 0
B17: Cuarto de Bomba Sub | C17: =SUMIFS(BD_REVIT!$H:$H,BD_REVIT!$C:$C,$C$10,BD_REVIT!$F:$F,LISTAS!$D$2) -> 1.98 | D17: =COUNTIF(BD_REVIT!$F:$F,LISTAS!$D$2) -> 46 | G17: TOTAL | H17: =SUM(H11:H16) -> 461 | I17: =SUM(I11:I16) -> 461 | J17: =SUM(J11:J16) -> 0
B18: Sótano 4 | C18: =SUMIFS(BD_REVIT!$H:$H,BD_REVIT!$C:$C,$C$10,BD_REVIT!$F:$F,LISTAS!$D$3) -> 31.36 | D18: =COUNTIF(BD_REVIT!$F:$F,LISTAS!$D$3) -> 17
B19: Sótano 3 | C19: =SUMIFS(BD_REVIT!$H:$H,BD_REVIT!$C:$C,$C$10,BD_REVIT!$F:$F,LISTAS!$D$4) -> 161.86 | D19: =COUNTIF(BD_REVIT!$F:$F,LISTAS!$D$4) -> 32
B20: Sótano 2 | C20: =SUMIFS(BD_REVIT!$H:$H,BD_REVIT!$C:$C,$C$10,BD_REVIT!$F:$F,LISTAS!$D$5) -> 193.88 | D20: =COUNTIF(BD_REVIT!$F:$F,LISTAS!$D$5) -> 35
B21: Sótano 1 | C21: =SUMIFS(BD_REVIT!$H:$H,BD_REVIT!$C:$C,$C$10,BD_REVIT!$F:$F,LISTAS!$D$6) -> 160.93 | D21: =COUNTIF(BD_REVIT!$F:$F,LISTAS!$D$6) -> 32
B22: Semisótano | C22: =SUMIFS(BD_REVIT!$H:$H,BD_REVIT!$C:$C,$C$10,BD_REVIT!$F:$F,LISTAS!$D$7) -> 59.51 | D22: =COUNTIF(BD_REVIT!$F:$F,LISTAS!$D$7) -> 37
B23: 1 | C23: =SUMIFS(BD_REVIT!$H:$H,BD_REVIT!$C:$C,$C$10,BD_REVIT!$F:$F,LISTAS!$D$8) -> 74.8 | D23: =COUNTIF(BD_REVIT!$F:$F,LISTAS!$D$8) -> 58
B24: 2 | C24: =SUMIFS(BD_REVIT!$H:$H,BD_REVIT!$C:$C,$C$10,BD_REVIT!$F:$F,LISTAS!$D$9) -> 17.36 | D24: =COUNTIF(BD_REVIT!$F:$F,LISTAS!$D$9) -> 44
B25: 3 | C25: =SUMIFS(BD_REVIT!$H:$H,BD_REVIT!$C:$C,$C$10,BD_REVIT!$F:$F,LISTAS!$D$10) -> 19.32 | D25: =COUNTIF(BD_REVIT!$F:$F,LISTAS!$D$10) -> 11
B26: 4 | C26: =SUMIFS(BD_REVIT!$H:$H,BD_REVIT!$C:$C,$C$10,BD_REVIT!$F:$F,LISTAS!$D$11) -> 19.32 | D26: =COUNTIF(BD_REVIT!$F:$F,LISTAS!$D$11) -> 13
B27: 5 | C27: =SUMIFS(BD_REVIT!$H:$H,BD_REVIT!$C:$C,$C$10,BD_REVIT!$F:$F,LISTAS!$D$12) -> 19.32 | D27: =COUNTIF(BD_REVIT!$F:$F,LISTAS!$D$12) -> 11
B28: 6 | C28: =SUMIFS(BD_REVIT!$H:$H,BD_REVIT!$C:$C,$C$10,BD_REVIT!$F:$F,LISTAS!$D$13) -> 19.32 | D28: =COUNTIF(BD_REVIT!$F:$F,LISTAS!$D$13) -> 11
B29: 7 | C29: =SUMIFS(BD_REVIT!$H:$H,BD_REVIT!$C:$C,$C$10,BD_REVIT!$F:$F,LISTAS!$D$14) -> 19.32 | D29: =COUNTIF(BD_REVIT!$F:$F,LISTAS!$D$14) -> 12
B30: 8 | C30: =SUMIFS(BD_REVIT!$H:$H,BD_REVIT!$C:$C,$C$10,BD_REVIT!$F:$F,LISTAS!$D$15) -> 19.32 | D30: =COUNTIF(BD_REVIT!$F:$F,LISTAS!$D$15) -> 11
B31: 9 | C31: =SUMIFS(BD_REVIT!$H:$H,BD_REVIT!$C:$C,$C$10,BD_REVIT!$F:$F,LISTAS!$D$16) -> 19.32 | D31: =COUNTIF(BD_REVIT!$F:$F,LISTAS!$D$16) -> 11
B32: 10 | C32: =SUMIFS(BD_REVIT!$H:$H,BD_REVIT!$C:$C,$C$10,BD_REVIT!$F:$F,LISTAS!$D$17) -> 19.32 | D32: =COUNTIF(BD_REVIT!$F:$F,LISTAS!$D$17) -> 12
B33: 11 | C33: =SUMIFS(BD_REVIT!$H:$H,BD_REVIT!$C:$C,$C$10,BD_REVIT!$F:$F,LISTAS!$D$18) -> 19.32 | D33: =COUNTIF(BD_REVIT!$F:$F,LISTAS!$D$18) -> 11
B34: 12 | C34: =SUMIFS(BD_REVIT!$H:$H,BD_REVIT!$C:$C,$C$10,BD_REVIT!$F:$F,LISTAS!$D$19) -> 19.32 | D34: =COUNTIF(BD_REVIT!$F:$F,LISTAS!$D$19) -> 11
B35: 13 | C35: =SUMIFS(BD_REVIT!$H:$H,BD_REVIT!$C:$C,$C$10,BD_REVIT!$F:$F,LISTAS!$D$20) -> 19.32 | D35: =COUNTIF(BD_REVIT!$F:$F,LISTAS!$D$20) -> 23
B36: 14 | C36: =SUMIFS(BD_REVIT!$H:$H,BD_REVIT!$C:$C,$C$10,BD_REVIT!$F:$F,LISTAS!$D$21) -> 18.65 | D36: =COUNTIF(BD_REVIT!$F:$F,LISTAS!$D$21) -> 15
B37: 15 | C37: =SUMIFS(BD_REVIT!$H:$H,BD_REVIT!$C:$C,$C$10,BD_REVIT!$F:$F,LISTAS!$D$22) -> 12.31 | D37: =COUNTIF(BD_REVIT!$F:$F,LISTAS!$D$22) -> 5

Sheet NIVEL
B3: PROYECTO: UNIQUE 76
B4: CUADRO DE CANTIDADES MONTAJE HIDROSANITARIO Y RCI
B5: Cap. 7 (RCI): cantidades globales calculadas desde BD_REVIT. Ítems 'Manual' se diligencian a mano.
A6: ITEM | B6: DESCRIPCIÓN | C6: UND. | D6: CANT. | E6: FUENTE
A7: 1 | B7: RED DE AGUAS LLUVIAS
A8: - | B8: Puntos, incluyen 1,00 mt a menos que se indique lo contrario
A9: 1.01 | B9: Puntos Aguas lluvias ø2" | C9: Un.
A10: 1.02 | B10: Puntos Aguas lluvias ø3" | C10: Un.
A11: 1.03 | B11: Puntos Aguas lluvias ø4" | C11: Un.
A12: 1.04 | B12: Pasantes en placa ø2" (sacanucleos) | C12: Un.
A13: 1.05 | B13: Pasantes en placa ø3" (sacanucleos) | C13: Un.
A14: 1.06 | B14: Pasantes en placa ø4" (sacanucleos) | C14: Un.
B15: Tubería Colectores Descolgados
A16: 1.07 | B16: Tubería De ø2" PVC-Sanitaria | C16: Ml.
A17: 1.08 | B17: Tubería De ø3" PVC-Sanitaria | C17: Ml.
A18: 1.09 | B18: Tubería De ø4" PVC-Sanitaria | C18: Ml.
A19: 1.10 | B19: Soporte pera 2" | C19: Un.
A20: 1.11 | B20: Soporte pera 3" | C20: Un.
A21: 1.12 | B21: Soporte pera 4" | C21: Un.
A22: 1.13 | B22: Pasante en muro contencion 4" | C22: Un.
A23: - | B23: Tubería Bajantes
A24: 1.14 | B24: Tuberia De ø4" PVC-Sanitaria | C24: Ml.
A25: 1.15 | B25: Tuberia De ø3" PVC-Sanitaria | C25: Ml.
A26: 1.16 | B26: Tuberia De ø2" PVC-Sanitaria | C26: Ml.
A27: 1.20 | B27: Soporte riel chanel 4" | C27: Un.
A28: 1.21 | B28: Soporte riel chanel 3" | C28: Un.
A29: 1.22 | B29: Soporte riel chanel 2" | C29: Un.
A30: - | B30: Tubería Colectores Enterrados
A31: 1.23 | B31: Tuberia De ø3" PVC-Sanitaria | C31: Ml.
A32: 1.24 | B32: Tuberia De ø4" PVC-Sanitaria | C32: Ml.
A33: - | B33: Cajas de Inspección en mamposteria (medidas internas)
A34: 1.25 | B34: Hmax. 1,00 mt 1,00 × 1,00 | C34: Un.
A35: 1.26 | B35: Hmax. 2,50 mt 2,50 × 2,00 Pozo eyector | C35: Un.
A36: - | B36: Movimientos de Tierra
A37: 1.27 | B37: Excavación en material Comun | C37: M3
A38: 1.28 | B38: Relleno Material Seleccionado | C38: M3
A39: - | B39: Uniones / Accesorios
B40: Tapon de Prueba D=2" | C40: Un.
B41: Tapon de Prueba D=3" | C41: Un.
B42: Tapon de Prueba D=4" | C42: Un.
...

Sheet BD_REVIT
A1: PROYECTO: UNIQUE 76
A2: BASE DE DATOS REVIT – RCI
A3: Edite solo la columna amarilla 'Código NIVEL' para asignar elementos. Ítem, Und. y Estado se calculan.
A5: ID | B5: Categoría | C5: Código NIVEL | D5: Ítem NIVEL | E5: Und. | F5: Nivel de piso | G5: Orden nivel | H5: Cantidad | I5: Familia / tipo Revit | J5: Descripción Revit | K5: Tamaño / diámetro | L5: Comentarios | M5: Estado | N5: Origen asignación
A6: 1 | B6: Accesorios | C6: 7.64 | D6: =IF(C6="","",IFERROR(INDEX(NIVEL!$B:$B,MATCH(C6,NIVEL!$A:$A,0)),"¡Código no existe!")) -> Junta de Expansión Antivibratoria D=2" | E6: =IF(C6="","",IFERROR(INDEX(NIVEL!$C:$C,MATCH(C6,NIVEL!$A:$A,0)),"")) -> Un. | F6: Nivel Cuarto de Bomba Sub | G6: =IFERROR(MATCH(F6,LISTAS!$D$2:$D$22,0),99) -> 1 | H6: 1 | I6: IDC_JUNTA DE EXPANCION ANTIVIBRATORIA: IDC_JUNTA DE EXPANCION ANTIVIBRATORIA | J6: JUNTA DE EXPANCIÓN ANTIVIBRATORIA | K6: 2"ø-2"ø | M6: =IF(C6="","SIN ASIGNAR","ASIGNADO") -> ASIGNADO | N6: Cruce Revit
A7: 2 | B7: Accesorios | C7: 7.69 | D7: =IF(C7="","",IFERROR(INDEX(NIVEL!$B:$B,MATCH(C7,NIVEL!$A:$A,0)),"¡Código no existe!")) -> Válvulas de Compuerta De ø2" | E7: =IF(C7="","",IFERROR(INDEX(NIVEL!$C:$C,MATCH(C7,NIVEL!$A:$A,0)),"")) -> Un. | F7: Nivel Cuarto de Bomba Sub | G7: =IFERROR(MATCH(F7,LISTAS!$D$2:$D$22,0),99) -> 1 | H7: 1 | I7: IDC_VALVULA DE COMPUERTA: 2 Inch | J7: VÁLVULA DE COMPUERTA | K7: 2"ø-2"ø | M7: =IF(C7="","SIN ASIGNAR","ASIGNADO") -> ASIGNADO | N7: Cruce Revit
A8: 3 | B8: Accesorios | C8: 7.69 | D8: =IF(C8="","",IFERROR(INDEX(NIVEL!$B:$B,MATCH(C8,NIVEL!$A:$A,0)),"¡Código no existe!")) -> Válvulas de Compuerta De ø2" | E8: =IF(C8="","",IFERROR(INDEX(NIVEL!$C:$C,MATCH(C8,NIVEL!$A:$A,0)),"")) -> Un. | F8: Nivel Cuarto de Bomba Sub | G8: =IFERROR(MATCH(F8,LISTAS!$D$2:$D$22,0),99) -> 1 | H8: 1 | I8: IDC_VALVULA DE COMPUERTA: 2 Inch | J8: VÁLVULA DE COMPUERTA | K8: 2"ø-2"ø | M8: =IF(C8="","SIN ASIGNAR","ASIGNADO") -> ASIGNADO | N8: Cruce Revit
A9: 4 | B9: Accesorios | C9: 7.69 | D9: =IF(C9="","",IFERROR(INDEX(NIVEL!$B:$B,MATCH(C9,NIVEL!$A:$A,0)),"¡Código no existe!")) -> Válvulas de Compuerta De ø2" | E9: =IF(C9="","",IFERROR(INDEX(NIVEL!$C:$C,MATCH(C9,NIVEL!$A:$A,0)),"")) -> Un. | F9: Nivel Cuarto de Bomba Sub | G9: =IFERROR(MATCH(F9,LISTAS!$D$2:$D$22,0),99) -> 1 | H9: 1 | I9: IDC_VALVULA DE COMPUERTA: 1 Inch | J9: VÁLVULA DE COMPUERTA | K9: 2"ø-2"ø | M9: =IF(C9="","SIN ASIGNAR","ASIGNADO") -> ASIGNADO | N9: Revisión 2026-10-08
A10: 5 | B10: Accesorios | C10: 7.85 | D10: =IF(C10="","",IFERROR(INDEX(NIVEL!$B:$B,MATCH(C10,NIVEL!$A:$A,0)),"¡Código no existe!")) -> Cabezal de Pruebas De ø6" con 3 salidas de ø2½" | E10: =IF(C10="","",IFERROR(INDEX(NIVEL!$C:$C,MATCH(C10,NIVEL!$A:$A,0)),"")) -> Un. | F10: Nivel Cuarto de Bomba Sub | G10: =IFERROR(MATCH(F10,LISTAS!$D$2:$D$22,0),99) -> 1 | H10: 1 | I10: IDC_CABEZAL DE PRUEBAS: IDC_CABEZAL DE PRUEBAS | J10: CABEZAL DE PRUEBA CON TRES SALIDAS ø2 1/2 | K10: 6"ø | M10: =IF(C10="","SIN ASIGNAR","ASIGNADO") -> ASIGNADO | N10: Cruce Revit
A11: 6 | B11: Accesorios | C11: 7.86 | D11: =IF(C11="","",IFERROR(INDEX(NIVEL!$B:$B,MATCH(C11,NIVEL!$A:$A,0)),"¡Código no existe!")) -> Caudalimetro D=6" | E11: =IF(C11="","",IFERROR(INDEX(NIVEL!$C:$C,MATCH(C11,NIVEL!$A:$A,0)),"")) -> Un. | F11: Nivel Cuarto de Bomba Sub | G11: =IFERROR(MATCH(F11,LISTAS!$D$2:$D$22,0),99) -> 1 | H11: 1 | I11: IDC_CAUDALIMETRO: Default | J11: CAUDALIMETRO | K11: 6"ø-6"ø | M11: =IF(C11="","SIN ASIGNAR","ASIGNADO") -> ASIGNADO | N11: Cruce Revit
A12: 7 | B12: Accesorios | C12: 7.19 | D12: =IF(C12="","",IFERROR(INDEX(NIVEL!$B:$B,MATCH(C12,NIVEL!$A:$A,0)),"¡Código no existe!")) -> Pasante en muro contencion 6" | E12: =IF(C12="","",IFERROR(INDEX(NIVEL!$C:$C,MATCH(C12,NIVEL!$A:$A,0)),"")) -> Un. | F12: Nivel Cuarto de Bomba Sub | G12: =IFERROR(MATCH(F12,LISTAS!$D$2:$D$22,0),99) -> 1 | H12: 1 | I12: IDC_PASE RUANA EXTREMOS BRIDADOS: IDC_PASE RUANA EXTREMOS BRIDADOS | J12: PASE EN ACERO CON RUANA PASA MUROS | K12: 6"ø-6"ø | M12: =IF(C12="","SIN ASIGNAR","ASIGNADO") -> ASIGNADO | N12: Revisión 2026-10-08
A13: 8 | B13: Accesorios | C13: 7.81 | D13: =IF(C13="","",IFERROR(INDEX(NIVEL!$B:$B,MATCH(C13,NIVEL!$A:$A,0)),"¡Código no existe!")) -> Placa Antivortice De ø6" | E13: =IF(C13="","",IFERROR(INDEX(NIVEL!$C:$C,MATCH(C13,NIVEL!$A:$A,0)),"")) -> Un. | F13: Nivel Cuarto de Bomba Sub | G13: =IFERROR(MATCH(F13,LISTAS!$D$2:$D$22,0),99) -> 1 | H13: 1 | I13: IDC_PLATINA ANTIVORTICE: PLATINA ANTIVORTICE | J13: PLATINA ANTI-VÓRTICE DE 0.30 * 0.30 m | K13: 6"ø-6"ø | M13: =IF(C13="","SIN ASIGNAR","ASIGNADO") -> ASIGNADO | N13: Cruce Revit
A14: 9 | B14: Accesorios | C14: 7.78 | D14: =IF(C14="","",IFERROR(INDEX(NIVEL!$B:$B,MATCH(C14,NIVEL!$A:$A,0)),"¡Código no existe!")) -> Válvulas OS&Y De ø6" | E14: =IF(C14="","",IFERROR(INDEX(NIVEL!$C:$C,MATCH(C14,NIVEL!$A:$A,0)),"")) -> Un. | F14: Nivel Cuarto de Bomba Sub | G14: =IFERROR(MATCH(F14,LISTAS!$D$2:$D$22,0),99) -> 1 | H14: 1 | I14: IDC_VALVULA DE VASTAGO: VALVULA OS&Y | J14: VÁLVULA DE VÁSTAGO | K14: 6"ø-6"ø | M14: =IF(C14="","SIN ASIGNAR","ASIGNADO") -> ASIGNADO | N14: Cruce Revit
A15: 10 | B15: Accesorios | C15: 7.78 | D15: =IF(C15="","",IFERROR(INDEX(NIVEL!$B:$B,MATCH(C15,NIVEL!$A:$A,0)),"¡Código no existe!")) -> Válvulas OS&Y De ø6" | E15: =IF(C15="","",IFERROR(INDEX(NIVEL!$C:$C,MATCH(C15,NIVEL!$A:$A,0)),"")) -> Un. | F15: Nivel Cuarto de Bomba Sub | G15: =IFERROR(MATCH(F15,LISTAS!$D$2:$D$22,0),99) -> 1 | H15: 1 | I15: IDC_VALVULA DE VASTAGO: VALVULA OS&Y | J15: VÁLVULA DE VÁSTAGO | K15: 6"ø-6"ø | M15: =IF(C15="","SIN ASIGNAR","ASIGNADO") -> ASIGNADO | N15: Cruce Revit
A16: 11 | B16: Accesorios | C16: 7.78 | D16: =IF(C16="","",IFERROR(INDEX(NIVEL!$B:$B,MATCH(C16,NIVEL!$A:$A,0)),"¡Código no existe!")) -> Válvulas OS&Y De ø6" | E16: =IF(C16="","",IFERROR(INDEX(NIVEL!$C:$C,MATCH(C16,NIVEL!$A:$A,0)),"")) -> Un. | F16: Nivel Cuarto de Bomba Sub | G16: =IFERROR(MATCH(F16,LISTAS!$D$2:$D$22,0),99) -> 1 | H16: 1 | I16: IDC_VALVULA DE VASTAGO: VALVULA OS&Y | J16: VÁLVULA DE VÁSTAGO | K16: 6"ø-6"ø | M16: =IF(C16="","SIN ASIGNAR","ASIGNADO") -> ASIGNADO | N16: Cruce Revit
A17: 12 | B17: Accesorios | C17: 7.78 | D17: =IF(C17="","",IFERROR(INDEX(NIVEL!$B:$B,MATCH(C17,NIVEL!$A:$A,0)),"¡Código no existe!")) -> Válvulas OS&Y De ø6" | E17: =IF(C17="","",IFERROR(INDEX(NIVEL!$C:$C,MATCH(C17,NIVEL!$A:$A,0)),"")) -> Un. | F17: Nivel Cuarto de Bomba Sub | G17: =IFERROR(MATCH(F17,LISTAS!$D$2:$D$22,0),99) -> 1 | H17: 1 | I17: IDC_VALVULA DE VASTAGO: VALVULA OS&Y | J17: VÁLVULA DE VÁSTAGO | K17: 6"ø-6"ø | M17: =IF(C17="","SIN ASIGNAR","ASIGNADO") -> ASIGNADO | N17: Cruce Revit
... A20: 15 | B20: Accesorios | C20: 7.78 | D20: =IF(C20="","",IFERROR(INDEX(NIVEL!$B:$B,MATCH(C20,NIVEL!$A:$A,0)),"¡Código no existe!")) -> Válvulas OS&Y De ø6" | E20: =IF(C20="","",IFERROR(INDEX(NIVEL!$C:$C,MATCH(C20,NIVEL!$A:$A,0)),"")) -> Un. | F20: Nivel Cuarto de Bomba Sub | G20: =IFERROR(MATCH(F20,LISTAS!$D$2:$D$22,0),99) -> 1 | H20: 1 | I20: IDC_VALVULA DE VASTAGO: VALVULA OS&Y | J20: VÁLVULA DE VÁSTAGO | K20: 6"ø-6"ø | M20: =IF(C20="","SIN ASIGNAR","ASIGNADO") -> ASIGNADO | N20: Cruce Revit
A21: 16 | B21: Accesorios | C21: 7.36 | D21: =IF(C21="","",IFERROR(INDEX(NIVEL!$B:$B,MATCH(C21,NIVEL!$A:$A,0)),"¡Código no existe!")) -> Suministro y Conexión válvula sensora de flujo y válvula de control abierto-cerrado ø2-1/2" | E21: =IF(C21="","",IFERROR(INDEX(NIVEL!$C:$C,MATCH(C21,NIVEL!$A:$A,0)),"")) -> Un. | F21: Nivel Sótano 3 | G21: =IFERROR(MATCH(F21,LISTAS!$D$2:$D$22,0),99) -> 3 | H21: 1 | I21: VKV EasyPac Floor Control Riser Manifold: GxG 2 1/2" EasyPac with Test and Drain w/ Relief Va | K21: 2 1/2"ø-2 1/2"ø-1 1/4"ø | M21: =IF(C21="","SIN ASIGNAR","ASIGNADO") -> ASIGNADO | N21: Revisión 2026-10-08
A22: 17 | B22: Accesorios | C22: 7.36 | D22: =IF(C22="","",IFERROR(INDEX(NIVEL!$B:$B,MATCH(C22,NIVEL!$A:$A,0)),"¡Código no existe!")) -> Suministro y Conexión válvula sensora de flujo y válvula de control abierto-cerrado ø2-1/2" | E22: =IF(C22="","",IFERROR(INDEX(NIVEL!$C:$C,MATCH(C22,NIVEL!$A:$A,0)),"")) -> Un. | F22: Nivel Sótano 2 | G22: =IFERROR(MATCH(F22,LISTAS!$D$2:$D$22,0),99) -> 4 | H22: 1 | I22: VKV EasyPac Floor Control Riser Manifold: GxG 2 1/2" EasyPac with Test and Drain w/ Relief Va | K22: 2 1/2"ø-2 1/2"ø-1 1/4"ø | M22: =IF(C22="","SIN ASIGNAR","ASIGNADO") -> ASIGNADO | N22: Revisión 2026-10-08
A23: 18 | B23: Accesorios | C23: 7.36 | D23: =IF(C23="","",IFERROR(INDEX(NIVEL!$B:$B,MATCH(C23,NIVEL!$A:$A,0)),"¡Código no existe!")) -> Suministro y Conexión válvula sensora de flujo y válvula de control abierto-cerrado ø2-1/2" | E23: =IF(C23="","",IFERROR(INDEX(NIVEL!$C:$C,MATCH(C23,NIVEL!$A:$A,0)),"")) -> Un. | F23: Nivel Sótano 1 | G23: =IFERROR(MATCH(F23,LISTAS!$D$2:$D$22,0),99) -> 5 | H23: 1 | I23: VKV EasyPac Floor Control Riser Manifold: GxG 2 1/2" EasyPac with Test and Drain w/ Relief Va | K23: 2 1/2"ø-2 1/2"ø-1 1/4"ø | M23: =IF(C23="","SIN ASIGNAR","ASIGNADO") -> ASIGNADO | N23: Revisión 2026-10-08
A24: 19 | B24: Accesorios | C24: 7.36 | D24: =IF(C24="","",IFERROR(INDEX(NIVEL!$B:$B,MATCH(C24,NIVEL!$A:$A,0)),"¡Código no existe!")) -> Suministro y Conexión válvula sensora de flujo y válvula de control abierto-cerrado ø2-1/2" | E24: =IF(C24="","",IFERROR(INDEX(NIVEL!$C:$C,MATCH(C24,NIVEL!$A:$A,0)),"")) -> Un. | F24: Nivel Semisótano | G24: =IFERROR(MATCH(F24,LISTAS!$D$2:$D$22,0),99) -> 6 | H24: 1 | I24: VKV EasyPac Floor Control Riser Manifold: GxG 2 1/2" EasyPac with Test and Drain w/ Relief Va | K24: 2 1/2"ø-2 1/2"ø-1 1/4"ø | M24: =IF(C24="","SIN ASIGNAR","ASIGNADO") -> ASIGNADO | N24: Revisión 2026-10-08
A25: 20 | B25: Accesorios | C25: 7.36 | D25: =IF(C25="","",IFERROR(INDEX(NIVEL!$B:$B,MATCH(C25,NIVEL!$A:$A,0)),"¡Código no existe!")) -> Suministro y Conexión válvula sensora de flujo y válvula de control abierto-cerrado ø2-1/2" | E25: =IF(C25="","",IFERROR(INDEX(NIVEL!$C:$C,MATCH(C25,NIVEL!$A:$A,0)),"")) -> Un. | F25: Nivel 1 | G25: =IFERROR(MATCH(F25,LISTAS!$D$2:$D$22,0),99) -> 7 | H25: 1 | I25: VKV EasyPac Floor Control Riser Manifold: GxG 2 1/2" EasyPac with Test and Drain w/ Relief Va | K25: 2 1/2"ø-2 1/2"ø-1 1/4"ø | M25: =IF(C25="","SIN ASIGNAR","ASIGNADO") -> ASIGNADO | N25: Revisión 2026-10-08
A26: 21 | B26: Accesorios | C26: 7.36 | D26: =IF(C26="","",IFERROR(INDEX(NIVEL!$B:$B,MATCH(C26,NIVEL!$A:$A,0)),"¡Código no existe!")) -> Suministro y Conexión válvula sensora de flujo y válvula de control abierto-cerrado ø2-1/2" | E26: =IF(C26="","",IFERROR(INDEX(NIVEL!$C:$C,MATCH(C26,NIVEL!$A:$A,0)),"")) -> Un. | F26: Nivel 1 | G26: =IFERROR(MATCH(F26,LISTAS!$D$2:$D$22,0),99) -> 7 | H26: 1 | I26: VKV EasyPac Floor Control Riser Manifold: GxG 2 1/2" EasyPac with Test and Drain w/ Relief Va | K26: 2 1/2"ø-2 1/2"ø-1 1/4"ø | M26: =IF(C26="","SIN ASIGNAR","ASIGNADO") -> ASIGNADO | N26: Revisión 2026-10-08
A27: 22 | B27: Accesorios | C27: 7.115 | D27: =IF(C27="","",IFERROR(INDEX(NIVEL!$B:$B,MATCH(C27,NIVEL!$A:$A,0)),"¡Código no existe!")) -> Válvula de Cheque Ranurado De ø4" | E27: =IF(C27="","",IFERROR(INDEX(NIVEL!$C:$C,MATCH(C27,NIVEL!$A:$A,0)),"")) -> Un. | F27: Nivel 1 | G27: =IFERROR(MATCH(F27,LISTAS!$D$2:$D$22,0),99) -> 7 | H27: 1 | I27: Fire-Protection_UWP_Swing-Check-Valve_Grooved: 4" | K27: 4"ø-4"ø | M27: =IF(C27="","SIN ASIGNAR","ASIGNADO") -> ASIGNADO | N27: Revisión 2026-10-08
A28: 23 | B28: Accesorios | C28: 7.36 | D28: =IF(C28="","",IFERROR(INDEX(NIVEL!$B:$B,MATCH(C28,NIVEL!$A:$A,0)),"¡Código no existe!")) -> Suministro y Conexión válvula sensora de flujo y válvula de control abierto-cerrado ø2-1/2" | E28: =IF(C28="","",IFERROR(INDEX(NIVEL!$C:$C,MATCH(C28,NIVEL!$A:$A,0)),"")) -> Un. | F28: Nivel 2 | G28: =IFERROR(MATCH(F28,LISTAS!$D$2:$D$22,0),99) -> 8 | H28: 1 | I28: VKV EasyPac Floor Control Riser Manifold: GxG 2 1/2" EasyPac with Test and Drain w/ Relief Va | K28: 2 1/2"ø-2 1/2"ø-1 1/4"ø | M28: =IF(C28="","SIN ASIGNAR","ASIGNADO") -> ASIGNADO | N28: Revisión 2026-10-08
A29: 24 | B29: Accesorios | C29: 7.114 | D29: =IF(C29="","",IFERROR(INDEX(NIVEL!$B:$B,MATCH(C29,NIVEL!$A:$A,0)),"¡Código no existe!")) -> Válvula de Compuerta De ø1" | E29: =IF(C29="","",IFERROR(INDEX(NIVEL!$C:$C,MATCH(C29,NIVEL!$A:$A,0)),"")) -> Un. | F29: Nivel 13 | G29: =IFERROR(MATCH(F29,LISTAS!$D$2:$D$22,0),99) -> 19 | H29: 1 | I29: IDC_VALVULA DE COMPUERTA1: 1 Inch 2 | J29: VÁLVULA DE COMPUERTA 1" | K29: 1"ø-1"ø | M29: =IF(C29="","SIN ASIGNAR","ASIGNADO") -> ASIGNADO | N29: Revisión 2026-10-08
A30: 25 | B30: Accesorios | C30: 7.114 | D30: =IF(C30="","",IFERROR(INDEX(NIVEL!$B:$B,MATCH(C30,NIVEL!$A:$A,0)),"¡Código no existe!")) -> Válvula de Compuerta De ø1" | E30: =IF(C30="","",IFERROR(INDEX(NIVEL!$C:$C,MATCH(C30,NIVEL!$A:$A,0)),"")) -> Un. | F30: Nivel 13 | G30: =IFERROR(MATCH(F30,LISTAS!$D$2:$D$22,0),99) -> 19 | H30: 1 | I30: IDC_VALVULA DE COMPUERTA1: 1 Inch 2 | J30: VÁLVULA DE COMPUERTA 1" | K30: 1"ø-1"ø | M30: =IF(C30="","SIN ASIGNAR","ASIGNADO") -> ASIGNADO | N30: Revisión 2026-10-08
A31: 26 | B31: Accesorios | C31: 7.89 | D31: =IF(C31="","",IFERROR(INDEX(NIVEL!$B:$B,MATCH(C31,NIVEL!$A:$A,0)),"¡Código no existe!")) -> Manometro 0-300 psi | E31: =IF(C31="","",IFERROR(INDEX(NIVEL!$C:$C,MATCH(C31,NIVEL!$A:$A,0)),"")) -> Un. | F31: Nivel 14 | G31: =IFERROR(MATCH(F31,LISTAS!$D$2:$D$22,0),99) -> 20 | H31: 1 | I31: IDC_MANOMETRO DE GLICERINA: IDC_MANOMETRO DE GLICERINA | J31: MANÓMETRO DE GLICERINA | K31: 1"ø | M31: =IF(C31="","SIN ASIGNAR","ASIGNADO") -> ASIGNADO | N31: Cruce Revit
A32: 27 | B32: Accesorios | C32: 7.89 | D32: =IF(C32="","",IFERROR(INDEX(NIVEL!$B:$B,MATCH(C32,NIVEL!$A:$A,0)),"¡Código no existe!")) -> Manometro 0-300 psi | E32: =IF(C32="","",IFERROR(INDEX(NIVEL!$C:$C,MATCH(C32,NIVEL!$A:$A,0)),"")) -> Un. | F32: Nivel 14 | G32: =IFERROR(MATCH(F32,LISTAS!$D$2:$D$22,0),99) -> 20 | H32: 1 | I32: IDC_MANOMETRO DE GLICERINA: IDC_MANOMETRO DE GLICERINA | J32: MANÓMETRO DE GLICERINA | K32: 1"ø | M32: =IF(C32="","SIN ASIGNAR","ASIGNADO") -> ASIGNADO | N32: Cruce Revit
A33: 28 | B33: Accesorios | C33: 7.87 | D33: =IF(C33="","",IFERROR(INDEX(NIVEL!$B:$B,MATCH(C33,NIVEL!$A:$A,0)),"¡Código no existe!")) -> Valvula Ventosa Restrictora UL/FM De ø1" | E33: =IF(C33="","",IFERROR(INDEX(NIVEL!$C:$C,MATCH(C33,NIVEL!$A:$A,0)),"")) -> Un. | F33: Nivel 14 | G33: =IFERROR(MATCH(F33,LISTAS!$D$2:$D$22,0),99) -> 20 | H33: 1 | I33: IDC_VALVULA EXPULSORA DE AIRE: 3/4” F x 3/8” F | J33: VÁLVULA EXPULSORA DE AIRE 1" | K33: 1"ø | M33: =IF(C33="","SIN ASIGNAR","ASIGNADO") -> ASIGNADO | N33: Cruce Revit
A34: 29 | B34: Accesorios | C34: 7.87 | D34: =IF(C34="","",IFERROR(INDEX(NIVEL!$B:$B,MATCH(C34,NIVEL!$A:$A,0)),"¡Código no existe!")) -> Valvula Ventosa Restrictora UL/FM De ø1" | E34: =IF(C34="","",IFERROR(INDEX(NIVEL!$C:$C,MATCH(C34,NIVEL!$A:$A,0)),"")) -> Un. | F34: Nivel 14 | G34: =IFERROR(MATCH(F34,LISTAS!$D$2:$D$22,0),99) -> 20 | H34: 1 | I34: IDC_VALVULA EXPULSORA DE AIRE: 3/4” F x 3/8” F | J34: VÁLVULA EXPULSORA DE AIRE 1" | K34: 1"ø | M34: =IF(C34="","SIN ASIGNAR","ASIGNADO") -> ASIGNADO | N34: Cruce Revit
A35: 30 | B35: Accesorios | C35: 7.114 | D35: =IF(C35="","",IFERROR(INDEX(NIVEL!$B:$B,MATCH(C35,NIVEL!$A:$A,0)),"¡Código no existe!")) -> Válvula de Compuerta De ø1" | E35: =IF(C35="","",IFERROR(INDEX(NIVEL!$C:$C,MATCH(C35,NIVEL!$A:$A,0)),"")) -> Un. | F35: Nivel 14 | G35: =IFERROR(MATCH(F35,LISTAS!$D$2:$D$22,0),99) -> 20 | H35: 1 | I35: IDC_VALVULA DE COMPUERTA1: 1 Inch 2 | J35: VÁLVULA DE COMPUERTA 1" | K35: 1"ø-1"ø | M35: =IF(C35="","SIN ASIGNAR","ASIGNADO") -> ASIGNADO | N35: Revisión 2026-10-08
A36: 31 | B36: Accesorios | C36: 7.114 | D36: =IF(C36="","",IFERROR(INDEX(NIVEL!$B:$B,MATCH(C36,NIVEL!$A:$A,0)),"¡Código no existe!")) -> Válvula de Compuerta De ø1" | E36: =IF(C36="","",IFERROR(INDEX(NIVEL!$C:$C,MATCH(C36,NIVEL!$A:$A,0)),"")) -> Un. | F36: Nivel 14 | G36: =IFERROR(MATCH(F36,LISTAS!$D$2:$D$22,0),99) -> 20 | H36: 1 | I36: IDC_VALVULA DE COMPUERTA1: 1 Inch 2 | J36: VÁLVULA DE COMPUERTA 1" | K36: 1"ø-1"ø | M36: =IF(C36="","SIN ASIGNAR","ASIGNADO") -> ASIGNADO | N36: Revisión 2026-10-08
A37: 32 | B37: Accesorios | C37: 7.114 | D37: =IF(C37="","",IFERROR(INDEX(NIVEL!$B:$B,MATCH(C37,NIVEL!$A:$A,0)),"¡Código no existe!")) -> Válvula de Compuerta De ø1" | E37: =IF(C37="","",IFERROR(INDEX(NIVEL!$C:$C,MATCH(C37,NIVEL!$A:$A,0)),"")) -> Un. | F37: Nivel 14 | G37: =IFERROR(MATCH(F37,LISTAS!$D$2:$D$22,0),99) -> 20 | H37: 1 | I37: IDC_VALVULA DE COMPUERTA1: 1 Inch 2 | J37: VÁLVULA DE COMPUERTA 1" | K37: 1"ø-1"ø | M37: =IF(C37="","SIN ASIGNAR","ASIGNADO") -> ASIGNADO | N37: Revisión 2026-10-08
A38: 33 | B38: Accesorios | C38: 7.114 | D38: =IF(C38="","",IFERROR(INDEX(NIVEL!$B:$B,MATCH(C38,NIVEL!$A:$A,0)),"¡Código no existe!")) -> Válvula de Compuerta De ø1" | E38: =IF(C38="","",IFERROR(INDEX(NIVEL!$C:$C,MATCH(C38,NIVEL!$A:$A,0)),"")) -> Un. | F38: Nivel 14 | G38: =IFERROR(MATCH(F38,LISTAS!$D$2:$D$22,0),99) -> 20 | H38: 1 | I38: IDC_VALVULA DE COMPUERTA1: 1 Inch 2 | J38: VÁLVULA DE COMPUERTA 1" | K38: 1"ø-1"ø | M38: =IF(C38="","SIN ASIGNAR","ASIGNADO") -> ASIGNADO | N38: Revisión 2026-10-08
A39: 34 | B39: Equipos | C39: 7.100 | D39: =IF(C39="","",IFERROR(INDEX(NIVEL!$B:$B,MATCH(C39,NIVEL!$A:$A,0)),"¡Código no existe!")) -> Suministro y Conexión Hidráulica Bomba Contraincendio. Condiciones de operación; Caudal Q=750 GPM, 187 MCA. Incluye tableros, suiches de nivel, tanque de Presión y demás accesorios para el correcto funcionamiento. No incluye cableado. (SE RECOMIENDA QUE LA INSTALACIÓN DEL EQUIPO DE BOMBEO, DESFOGUE Y TANQUE DIESEL SEA REALIZADA POR EL MISMO PROVEEDOR DEL SUMINISTRO). | E39: =IF(C39="","",IFERROR(INDEX(NIVEL!$C:$C,MATCH(C39,NIVEL!$A:$A,0)),"")) -> Un. | G39: =IFERROR(MATCH(F39,LISTAS!$D$2:$D$22,0),99) -> 99 | H39: 1 | I39: LS model | M39: =IF(C39="","SIN ASIGNAR","ASIGNADO") -> ASIGNADO | N39: Revisión 2026-10-08
A40: 35 | B40: Equipos | C40: 7.101 | D40: =IF(C40="","",IFERROR(INDEX(NIVEL!$B:$B,MATCH(C40,NIVEL!$A:$A,0)),"¡Código no existe!")) -> Suministro y Conexión Hidráulica Bomba Jockey Caudal Q= 7,5 GPM, HT= 142 m, incluye tablero, suiches de nivel, presóstato, manómetro y demás accesorios para el correcto funcionamiento. No incluye cableado. (SE RECOMIENDA QUE LA INSTALACIÓN DEL EQUIPO DE BOMBEO SEA REALIZADA POR EL MISMO PROVEEDOR DEL SUMINISTRO). | E40: =IF(C40="","",IFERROR(INDEX(NIVEL!$C:$C,MATCH(C40,NIVEL!$A:$A,0)),"")) -> Un. | G40: =IFERROR(MATCH(F40,LISTAS!$D$2:$D$22,0),99) -> 99 | H40: 1 | I40: USE TYPE CATALOG | M40: =IF(C40="","SIN ASIGNAR","ASIGNADO") -> ASIGNADO | N40: Revisión 2026-10-08
A41: 36 | B41: Equipos | C41: 7.116 | D41: =IF(C41="","",IFERROR(INDEX(NIVEL!$B:$B,MATCH(C41,NIVEL!$A:$A,0)),"¡Código no existe!")) -> Base en concreto para equipo de bombeo | E41: =IF(C41="","",IFERROR(INDEX(NIVEL!$C:$C,MATCH(C41,NIVEL!$A:$A,0)),"")) -> Un. | G41: =IFERROR(MATCH(F41,LISTAS!$D$2:$D$22,0),99) -> 99 | H41: 1 | I41: IDC_BASE DE CONCRETO | M41: =IF(C41="","SIN ASIGNAR","ASIGNADO") -> ASIGNADO | N41: Revisión 2026-10-08
A42: 37 | B42: Rociadores | C42: 7.06 | D42: =IF(C42="","",IFERROR(INDEX(NIVEL!$B:$B,MATCH(C42,NIVEL!$A:$A,0)),"¡Código no existe!")) -> Rociador Sprinkler ø1/2" K=11,2 extendida QR | E42: =IF(C42="","",IFERROR(INDEX(NIVEL!$C:$C,MATCH(C42,NIVEL!$A:$A,0)),"")) -> Un. | F42: Nivel Sótano 4 | G42: =IFERROR(MATCH(F42,LISTAS!$D$2:$D$22,0),99) -> 2 | H42: 33 | I42: IDC_ROCIADORES: ROCIADOR COLGANTE (COB ESTANDAR) | L42: SPK | M42: =IF(C42="","SIN ASIGNAR","ASIGNADO") -> ASIGNADO | N42: Cruce Revit
A43: 38 | B43: Rociadores | C43: 7.06 | D43: =IF(C43="","",IFERROR(INDEX(NIVEL!$B:$B,MATCH(C43,NIVEL!$A:$A,0)),"¡Código no existe!")) -> Rociador Sprinkler ø1/2" K=11,2 extendida QR | E43: =IF(C43="","",IFERROR(INDEX(NIVEL!$C:$C,MATCH(C43,NIVEL!$A:$A,0)),"")) -> Un. | F43: Nivel Sótano 2 | G43: =IFERROR(MATCH(F43,LISTAS!$D$2:$D$22,0),99) -> 4 | H43: 46 | I43: IDC_ROCIADORES: ROCIADOR COLGANTE (COB ESTANDAR) | L43: SPK | M43: =IF(C43="","SIN ASIGNAR","ASIGNADO") -> ASIGNADO | N43: Cruce Revit
...

Sheet CRUCE RCI
A1: PROYECTO: UNIQUE 76
A2: CRUCE DE CANTIDADES RCI POR NIVEL DE PISO
A3: Suma de BD_REVIT por ítem y nivel. 'Dif.' compara contra la cantidad global de NIVEL (debe ser 0).
D4: Nivel Cuarto de Bomba Sub | E4: Nivel Sótano 4 | F4: Nivel Sótano 3 | G4: Nivel Sótano 2 | H4: Nivel Sótano 1 | I4: Nivel Semisótano | J4: Nivel 1 | K4: Nivel 2 | L4: Nivel 3 | M4: Nivel 4 | N4: Nivel 5 | O4: Nivel 6 | P4: Nivel 7 | Q4: Nivel 8 | R4: Nivel 9 | S4: Nivel 10 | T4: Nivel 11 | U4: Nivel 12 | V4: Nivel 13 | W4: Nivel 14 | X4: Nivel 15 | Y4: =
A5: Código | B5: Descripción | C5: Und. | D5: C. Bomba | E5: Sótano 4 | F5: Sótano 3 | G5: Sótano 2 | H5: Sótano 1 | I5: Semisótano | J5: 1 | K5: 2 | L5: 3 | M5: 4 | N5: 5 | O5: 6 | P5: 7 | Q5: 8 | R5: 9 | S5: 10 | T5: 11 | U5: 12 | V5: 13 | W5: 14 | X5: 15 | Y5: Sin nivel | Z5: TOTAL | AA5: NIVEL | AB5: Dif.
A6: 7.01 | B6: Puntos Conexión Valvula Angular 2-1/2 | C6: Un. | D6: =SUMIFS(BD_REVIT!$H:$H,BD_REVIT!$C:$C,$A6,BD_REVIT!$F:$F,D$4) -> 0 | E6: =SUMIFS(BD_REVIT!$H:$H,BD_REVIT!$C:$C,$A6,BD_REVIT!$F:$F,E$4) -> 0 | F6: =SUMIFS(BD_REVIT!$H:$H,BD_REVIT!$C:$C,$A6,BD_REVIT!$F:$F,F$4) -> 0 | G6: =SUMIFS(BD_REVIT!$H:$H,BD_REVIT!$C:$C,$A6,BD_REVIT!$F:$F,G$4) -> 0 | H6: =SUMIFS(BD_REVIT!$H:$H,BD_REVIT!$C:$C,$A6,BD_REVIT!$F:$F,H$4) -> 0 | I6: =SUMIFS(BD_REVIT!$H:$H,BD_REVIT!$C:$C,$A6,BD_REVIT!$F:$F,I$4) -> 0 | J6: =SUMIFS(BD_REVIT!$H:$H,BD_REVIT!$C:$C,$A6,BD_REVIT!$F:$F,J$4) -> 0 | K6: =SUMIFS(BD_REVIT!$H:$H,BD_REVIT!$C:$C,$A6,BD_REVIT!$F:$F,K$4) -> 0 | ... Y6: =SUMIFS(BD_REVIT!$H:$H,BD_REVIT!$C:$C,$A6,BD_REVIT!$F:$F,Y$4) -> 0 | Z6: =SUM(D6:Y6) -> 0 | AA6: =NIVEL!D387 -> 0 | AB6: =ROUND(Z6-AA6,2) -> 0
A7: 7.02 | B7: Puntos AC 1-1/2" Gabinetes Tipo 2 | C7: Un. | D7: =SUMIFS(BD_REVIT!$H:$H,BD_REVIT!$C:$C,$A7,BD_REVIT!$F:$F,D$4) -> 0 | E7: =SUMIFS(BD_REVIT!$H:$H,BD_REVIT!$C:$C,$A7,BD_REVIT!$F:$F,E$4) -> 0 | F7: =SUMIFS(BD_REVIT!$H:$H,BD_REVIT!$C:$C,$A7,BD_REVIT!$F:$F,F$4) -> 0 | G7: =SUMIFS(BD_REVIT!$H:$H,BD_REVIT!$C:$C,$A7,BD_REVIT!$F:$F,G$4) -> 0 | H7: =SUMIFS(BD_REVIT!$H:$H,BD_REVIT!$C:$C,$A7,BD_REVIT!$F:$F,H$4) -> 0 | I7: =SUMIFS(BD_REVIT!$H:$H,BD_REVIT!$C:$C,$A7,BD_REVIT!$F:$F,I$4) -> 0 | J7: =SUMIFS(BD_REVIT!$H:$H,BD_REVIT!$C:$C,$A7,BD_REVIT!$F:$F,J$4) -> 0 | K7: =SUMIFS(BD_REVIT!$H:$H,BD_REVIT!$C:$C,$A7,BD_REVIT!$F:$F,K$4) -> 0 | ... Y7: =SUMIFS(BD_REVIT!$H:$H,BD_REVIT!$C:$C,$A7,BD_REVIT!$F:$F,Y$4) -> 0 | Z7: =SUM(D7:Y7) -> 0 | AA7: =NIVEL!D388 -> 0 | AB7: =ROUND(Z7-AA7,2) -> 0
A8: 7.03 | B8: Puntos Sprinkler - AC 1" | C8: Un. | D8: =SUMIFS(BD_REVIT!$H:$H,BD_REVIT!$C:$C,$A8,BD_REVIT!$F:$F,D$4) -> 0 | E8: =SUMIFS(BD_REVIT!$H:$H,BD_REVIT!$C:$C,$A8,BD_REVIT!$F:$F,E$4) -> 0 | F8: =SUMIFS(BD_REVIT!$H:$H,BD_REVIT!$C:$C,$A8,BD_REVIT!$F:$F,F$4) -> 0 | G8: =SUMIFS(BD_REVIT!$H:$H,BD_REVIT!$C:$C,$A8,BD_REVIT!$F:$F,G$4) -> 0 | H8: =SUMIFS(BD_REVIT!$H:$H,BD_REVIT!$C:$C,$A8,BD_REVIT!$F:$F,H$4) -> 0 | I8: =SUMIFS(BD_REVIT!$H:$H,BD_REVIT!$C:$C,$A8,BD_REVIT!$F:$F,I$4) -> 0 | J8: =SUMIFS(BD_REVIT!$H:$H,BD_REVIT!$C:$C,$A8,BD_REVIT!$F:$F,J$4) -> 0 | K8: =SUMIFS(BD_REVIT!$H:$H,BD_REVIT!$C:$C,$A8,BD_REVIT!$F:$F,K$4) -> 0 | ... Y8: =SUMIFS(BD_REVIT!$H:$H,BD_REVIT!$C:$C,$A8,BD_REVIT!$F:$F,Y$4) -> 0 | Z8: =SUM(D8:Y8) -> 0 | AA8: =NIVEL!D389 -> 0 | AB8: =ROUND(Z8-AA8,2) -> 0
A9: 7.04 | B9: Suministro y Conexión Gabinete tipo 2 en Lamina Cold Rolled Calibre 20 de 0.77×0.77×0.22, Válvula angular 1½" Regulada, Soporte tipo canasta, Manguera fibra poliester y caucho 1½"×100', Boquilla chorro y niebla 1½"-Hacha pico 4½" lbs, Llave Spaner-Extintor de polvo | C9: Un. | D9: =SUMIFS(BD_REVIT!$H:$H,BD_REVIT!$C:$C,$A9,BD_REVIT!$F:$F,D$4) -> 0 | E9: =SUMIFS(BD_REVIT!$H:$H,BD_REVIT!$C:$C,$A9,BD_REVIT!$F:$F,E$4) -> 0 | F9: =SUMIFS(BD_REVIT!$H:$H,BD_REVIT!$C:$C,$A9,BD_REVIT!$F:$F,F$4) -> 0 | G9: =SUMIFS(BD_REVIT!$H:$H,BD_REVIT!$C:$C,$A9,BD_REVIT!$F:$F,G$4) -> 0 | H9: =SUMIFS(BD_REVIT!$H:$H,BD_REVIT!$C:$C,$A9,BD_REVIT!$F:$F,H$4) -> 0 | I9: =SUMIFS(BD_REVIT!$H:$H,BD_REVIT!$C:$C,$A9,BD_REVIT!$F:$F,I$4) -> 0 | J9: =SUMIFS(BD_REVIT!$H:$H,BD_REVIT!$C:$C,$A9,BD_REVIT!$F:$F,J$4) -> 0 | K9: =SUMIFS(BD_REVIT!$H:$H,BD_REVIT!$C:$C,$A9,BD_REVIT!$F:$F,K$4) -> 0 | ... Y9: =SUMIFS(BD_REVIT!$H:$H,BD_REVIT!$C:$C,$A9,BD_REVIT!$F:$F,Y$4) -> 0 | Z9: =SUM(D9:Y9) -> 0 | AA9: =NIVEL!D391 -> 0 | AB9: =ROUND(Z9-AA9,2) -> 0
A10: 7.05 | B10: Rociador Sprinkler ø1/2" K=5,6 estándar QR | C10: Un. | D10: =SUMIFS(BD_REVIT!$H:$H,BD_REVIT!$C:$C,$A10,BD_REVIT!$F:$F,D$4) -> 0 | E10: =SUMIFS(BD_REVIT!$H:$H,BD_REVIT!$C:$C,$A10,BD_REVIT!$F:$F,E$4) -> 0 | F10: =SUMIFS(BD_REVIT!$H:$H,BD_REVIT!$C:$C,$A10,BD_REVIT!$F:$F,F$4) -> 0 | G10: =SUMIFS(BD_REVIT!$H:$H,BD_REVIT!$C:$C,$A10,BD_REVIT!$F:$F,G$4) -> 0 | H10: =SUMIFS(BD_REVIT!$H:$H,BD_REVIT!$C:$C,$A10,BD_REVIT!$F:$F,H$4) -> 0 | I10: =SUMIFS(BD_REVIT!$H:$H,BD_REVIT!$C:$C,$A10,BD_REVIT!$F:$F,I$4) -> 0 | J10: =SUMIFS(BD_REVIT!$H:$H,BD_REVIT!$C:$C,$A10,BD_REVIT!$F:$F,J$4) -> 94 | K10: =SUMIFS(BD_REVIT!$H:$H,BD_REVIT!$C:$C,$A10,BD_REVIT!$F:$F,K$4) -> 24 | ... Y10: =SUMIFS(BD_REVIT!$H:$H,BD_REVIT!$C:$C,$A10,BD_REVIT!$F:$F,Y$4) -> 0 | Z10: =SUM(D10:Y10) -> 118 | AA10: =NIVEL!D393 -> 118 | AB10: =ROUND(Z10-AA10,2) -> 0
A11: 7.06 | B11: Rociador Sprinkler ø1/2" K=11,2 extendida QR | C11: Un. | D11: =SUMIFS(BD_REVIT!$H:$H,BD_REVIT!$C:$C,$A11,BD_REVIT!$F:$F,D$4) -> 0 | E11: =SUMIFS(BD_REVIT!$H:$H,BD_REVIT!$C:$C,$A11,BD_REVIT!$F:$F,E$4) -> 33 | F11: =SUMIFS(BD_REVIT!$H:$H,BD_REVIT!$C:$C,$A11,BD_REVIT!$F:$F,F$4) -> 0 | G11: =SUMIFS(BD_REVIT!$H:$H,BD_REVIT!$C:$C,$A11,BD_REVIT!$F:$F,G$4) -> 46 | H11: =SUMIFS(BD_REVIT!$H:$H,BD_REVIT!$C:$C,$A11,BD_REVIT!$F:$F,H$4) -> 72 | I11: =SUMIFS(BD_REVIT!$H:$H,BD_REVIT!$C:$C,$A11,BD_REVIT!$F:$F,I$4) -> 73 | J11: =SUMIFS(BD_REVIT!$H:$H,BD_REVIT!$C:$C,$A11,BD_REVIT!$F:$F,J$4) -> 0 | K11: =SUMIFS(BD_REVIT!$H:$H,BD_REVIT!$C:$C,$A11,BD_REVIT!$F:$F,K$4) -> 0 | ... Y11: =SUMIFS(BD_REVIT!$H:$H,BD_REVIT!$C:$C,$A11,BD_REVIT!$F:$F,Y$4) -> 0 | Z11: =SUM(D11:Y11) -> 224 | AA11: =NIVEL!D394 -> 224 | AB11: =ROUND(Z11-AA11,2) -> 0
A12: 7.07 | B12: Tubería A.C. Sche 10 De ø1" | C12: Ml. | D12: =SUMIFS(BD_REVIT!$H:$H,BD_REVIT!$C:$C,$A12,BD_REVIT!$F:$F,D$4) -> 0.25 | E12: =SUMIFS(BD_REVIT!$H:$H,BD_REVIT!$C:$C,$A12,BD_REVIT!$F:$F,E$4) -> 0.94 | F12: =SUMIFS(BD_REVIT!$H:$H,BD_REVIT!$C:$C,$A12,BD_REVIT!$F:$F,F$4) -> 5.07 | G12: =SUMIFS(BD_REVIT!$H:$H,BD_REVIT!$C:$C,$A12,BD_REVIT!$F:$F,G$4) -> 11.49 | H12: =SUMIFS(BD_REVIT!$H:$H,BD_REVIT!$C:$C,$A12,BD_REVIT!$F:$F,H$4) -> 6.64 | I12: =SUMIFS(BD_REVIT!$H:$H,BD_REVIT!$C:$C,$A12,BD_REVIT!$F:$F,I$4) -> 0.41 | J12: =SUMIFS(BD_REVIT!$H:$H,BD_REVIT!$C:$C,$A12,BD_REVIT!$F:$F,J$4) -> 12.34 | K12: =SUMIFS(BD_REVIT!$H:$H,BD_REVIT!$C:$C,$A12,BD_REVIT!$F:$F,K$4) -> 4.55 | ... Y12: =SUMIFS(BD_REVIT!$H:$H,BD_REVIT!$C:$C,$A12,BD_REVIT!$F:$F,Y$4) -> 0 | Z12: =SUM(D12:Y12) -> 53.83 | AA12: =NIVEL!D396 -> 53.83 | AB12: =ROUND(Z12-AA12,2) -> 0
A13: 7.103 | B13: Tubería A.C. Sche 10 De ø1 1/4" | C13: Ml. | D13: =SUMIFS(BD_REVIT!$H:$H,BD_REVIT!$C:$C,$A13,BD_REVIT!$F:$F,D$4) -> 0 | E13: =SUMIFS(BD_REVIT!$H:$H,BD_REVIT!$C:$C,$A13,BD_REVIT!$F:$F,E$4) -> 0 | F13: =SUMIFS(BD_REVIT!$H:$H,BD_REVIT!$C:$C,$A13,BD_REVIT!$F:$F,F$4) -> 0.22 | G13: =SUMIFS(BD_REVIT!$H:$H,BD_REVIT!$C:$C,$A13,BD_REVIT!$F:$F,G$4) -> 0.22 | H13: =SUMIFS(BD_REVIT!$H:$H,BD_REVIT!$C:$C,$A13,BD_REVIT!$F:$F,H$4) -> 0.22 | I13: =SUMIFS(BD_REVIT!$H:$H,BD_REVIT!$C:$C,$A13,BD_REVIT!$F:$F,I$4) -> 0.22 | J13: =SUMIFS(BD_REVIT!$H:$H,BD_REVIT!$C:$C,$A13,BD_REVIT!$F:$F,J$4) -> 0.54 | K13: =SUMIFS(BD_REVIT!$H:$H,BD_REVIT!$C:$C,$A13,BD_REVIT!$F:$F,K$4) -> 0.22 | ... Y13: =SUMIFS(BD_REVIT!$H:$H,BD_REVIT!$C:$C,$A13,BD_REVIT!$F:$F,Y$4) -> 0 | Z13: =SUM(D13:Y13) -> 1.64 | AA13: =NIVEL!D397 -> 1.64 | AB13: =ROUND(Z13-AA13,2) -> 0
A14: 7.08 | B14: Tubería A.C. Sche 10 De ø1 1/2" | C14: Ml. | D14: =SUMIFS(BD_REVIT!$H:$H,BD_REVIT!$C:$C,$A14,BD_REVIT!$F:$F,D$4) -> 1.98 | E14: =SUMIFS(BD_REVIT!$H:$H,BD_REVIT!$C:$C,$A14,BD_REVIT!$F:$F,E$4) -> 31.36 | F14: =SUMIFS(BD_REVIT!$H:$H,BD_REVIT!$C:$C,$A14,BD_REVIT!$F:$F,F$4) -> 161.86 | G14: =SUMIFS(BD_REVIT!$H:$H,BD_REVIT!$C:$C,$A14,BD_REVIT!$F:$F,G$4) -> 193.88 | H14: =SUMIFS(BD_REVIT!$H:$H,BD_REVIT!$C:$C,$A14,BD_REVIT!$F:$F,H$4) -> 160.93 | I14: =SUMIFS(BD_REVIT!$H:$H,BD_REVIT!$C:$C,$A14,BD_REVIT!$F:$F,I$4) -> 59.51 | J14: =SUMIFS(BD_REVIT!$H:$H,BD_REVIT!$C:$C,$A14,BD_REVIT!$F:$F,J$4) -> 74.8 | K14: =SUMIFS(BD_REVIT!$H:$H,BD_REVIT!$C:$C,$A14,BD_REVIT!$F:$F,K$4) -> 17.36 | ... Y14: =SUMIFS(BD_REVIT!$H:$H,BD_REVIT!$C:$C,$A14,BD_REVIT!$F:$F,Y$4) -> 0 | Z14: =SUM(D14:Y14) -> 945.16 | AA14: =NIVEL!D398 -> 945.16 | AB14: =ROUND(Z14-AA14,2) -> 0
A15: 7.104 | B15: Tubería A.C. Sche 10 De ø2" | C15: Ml. | D15: =SUMIFS(BD_REVIT!$H:$H,BD_REVIT!$C:$C,$A15,BD_REVIT!$F:$F,D$4) -> 3.45 | E15: =SUMIFS(BD_REVIT!$H:$H,BD_REVIT!$C:$C,$A15,BD_REVIT!$F:$F,E$4) -> 0 | F15: =SUMIFS(BD_REVIT!$H:$H,BD_REVIT!$C:$C,$A15,BD_REVIT!$F:$F,F$4) -> 0 | G15: =SUMIFS(BD_REVIT!$H:$H,BD_REVIT!$C:$C,$A15,BD_REVIT!$F:$F,G$4) -> 0 | H15: =SUMIFS(BD_REVIT!$H:$H,BD_REVIT!$C:$C,$A15,BD_REVIT!$F:$F,H$4) -> 0 | I15: =SUMIFS(BD_REVIT!$H:$H,BD_REVIT!$C:$C,$A15,BD_REVIT!$F:$F,I$4) -> 0 | J15: =SUMIFS(BD_REVIT!$H:$H,BD_REVIT!$C:$C,$A15,BD_REVIT!$F:$F,J$4) -> 73.55 | K15: =SUMIFS(BD_REVIT!$H:$H,BD_REVIT!$C:$C,$A15,BD_REVIT!$F:$F,K$4) -> 58.67 | ... Y15: =SUMIFS(BD_REVIT!$H:$H,BD_REVIT!$C:$C,$A15,BD_REVIT!$F:$F,Y$4) -> 0 | Z15: =SUM(D15:Y15) -> 136.2 | AA15: =NIVEL!D399 -> 136.2 | AB15: =ROUND(Z15-AA15,2) -> 0
A16: 7.09 | B16: Tubería A.C. Sche 10 De ø2 1/2" | C16: Ml. | D16: =SUMIFS(BD_REVIT!$H:$H,BD_REVIT!$C:$C,$A16,BD_REVIT!$F:$F,D$4) -> 0 | E16: =SUMIFS(BD_REVIT!$H:$H,BD_REVIT!$C:$C,$A16,BD_REVIT!$F:$F,E$4) -> 0 | F16: =SUMIFS(BD_REVIT!$H:$H,BD_REVIT!$C:$C,$A16,BD_REVIT!$F:$F,F$4) -> 3.49 | G16: =SUMIFS(BD_REVIT!$H:$H,BD_REVIT!$C:$C,$A16,BD_REVIT!$F:$F,G$4) -> 3.5 | H16: =SUMIFS(BD_REVIT!$H:$H,BD_REVIT!$C:$C,$A16,BD_REVIT!$F:$F,H$4) -> 3.49 | I16: =SUMIFS(BD_REVIT!$H:$H,BD_REVIT!$C:$C,$A16,BD_REVIT!$F:$F,I$4) -> 3.6 | J16: =SUMIFS(BD_REVIT!$H:$H,BD_REVIT!$C:$C,$A16,BD_REVIT!$F:$F,J$4) -> 9.33 | K16: =SUMIFS(BD_REVIT!$H:$H,BD_REVIT!$C:$C,$A16,BD_REVIT!$F:$F,K$4) -> 7.89 | ... Y16: =SUMIFS(BD_REVIT!$H:$H,BD_REVIT!$C:$C,$A16,BD_REVIT!$F:$F,Y$4) -> 0 | Z16: =SUM(D16:Y16) -> 31.3 | AA16: =NIVEL!D400 -> 31.3 | AB16: =ROUND(Z16-AA16,2) -> 0
A17: 7.10 | B17: Tubería A.C. Sche 10 De ø3" | C17: Ml. | D17: =SUMIFS(BD_REVIT!$H:$H,BD_REVIT!$C:$C,$A17,BD_REVIT!$F:$F,D$4) -> 0 | E17: =SUMIFS(BD_REVIT!$H:$H,BD_REVIT!$C:$C,$A17,BD_REVIT!$F:$F,E$4) -> 75.45 | F17: =SUMIFS(BD_REVIT!$H:$H,BD_REVIT!$C:$C,$A17,BD_REVIT!$F:$F,F$4) -> 168.9 | G17: =SUMIFS(BD_REVIT!$H:$H,BD_REVIT!$C:$C,$A17,BD_REVIT!$F:$F,G$4) -> 136.59 | H17: =SUMIFS(BD_REVIT!$H:$H,BD_REVIT!$C:$C,$A17,BD_REVIT!$F:$F,H$4) -> 100.58 | I17: =SUMIFS(BD_REVIT!$H:$H,BD_REVIT!$C:$C,$A17,BD_REVIT!$F:$F,I$4) -> 85.95 | J17: =SUMIFS(BD_REVIT!$H:$H,BD_REVIT!$C:$C,$A17,BD_REVIT!$F:$F,J$4) -> 189.28 | K17: =SUMIFS(BD_REVIT!$H:$H,BD_REVIT!$C:$C,$A17,BD_REVIT!$F:$F,K$4) -> 23.05 | ... Y17: =SUMIFS(BD_REVIT!$H:$H,BD_REVIT!$C:$C,$A17,BD_REVIT!$F:$F,Y$4) -> 0 | Z17: =SUM(D17:Y17) -> 779.8 | AA17: =NIVEL!D401 -> 779.8 | AB17: =ROUND(Z17-AA17,2) -> 0
A18: 7.11 | B18: Tubería A.C. Sche 10 De ø4" | C18: Ml. | D18: =SUMIFS(BD_REVIT!$H:$H,BD_REVIT!$C:$C,$A18,BD_REVIT!$F:$F,D$4) -> 0.95 | E18: =SUMIFS(BD_REVIT!$H:$H,BD_REVIT!$C:$C,$A18,BD_REVIT!$F:$F,E$4) -> 0 | F18: =SUMIFS(BD_REVIT!$H:$H,BD_REVIT!$C:$C,$A18,BD_REVIT!$F:$F,F$4) -> 0 | G18: =SUMIFS(BD_REVIT!$H:$H,BD_REVIT!$C:$C,$A18,BD_REVIT!$F:$F,G$4) -> 0 | H18: =SUMIFS(BD_REVIT!$H:$H,BD_REVIT!$C:$C,$A18,BD_REVIT!$F:$F,H$4) -> 0 | I18: =SUMIFS(BD_REVIT!$H:$H,BD_REVIT!$C:$C,$A18,BD_REVIT!$F:$F,I$4) -> 0 | J18: =SUMIFS(BD_REVIT!$H:$H,BD_REVIT!$C:$C,$A18,BD_REVIT!$F:$F,J$4) -> 13.75 | K18: =SUMIFS(BD_REVIT!$H:$H,BD_REVIT!$C:$C,$A18,BD_REVIT!$F:$F,K$4) -> 0 | ... Y18: =SUMIFS(BD_REVIT!$H:$H,BD_REVIT!$C:$C,$A18,BD_REVIT!$F:$F,Y$4) -> 0 | Z18: =SUM(D18:Y18) -> 14.7 | AA18: =NIVEL!D402 -> 14.7 | AB18: =ROUND(Z18-AA18,2) -> 0
A19: 7.12 | B19: Tubería A.C. Sche 10 De ø6" | C19: Ml. | D19: =SUMIFS(BD_REVIT!$H:$H,BD_REVIT!$C:$C,$A19,BD_REVIT!$F:$F,D$4) -> 73.21 | E19: =SUMIFS(BD_REVIT!$H:$H,BD_REVIT!$C:$C,$A19,BD_REVIT!$F:$F,E$4) -> 0.43 | F19: =SUMIFS(BD_REVIT!$H:$H,BD_REVIT!$C:$C,$A19,BD_REVIT!$F:$F,F$4) -> 2.63 | G19: =SUMIFS(BD_REVIT!$H:$H,BD_REVIT!$C:$C,$A19,BD_REVIT!$F:$F,G$4) -> 6.07 | H19: =SUMIFS(BD_REVIT!$H:$H,BD_REVIT!$C:$C,$A19,BD_REVIT!$F:$F,H$4) -> 2.9 | I19: =SUMIFS(BD_REVIT!$H:$H,BD_REVIT!$C:$C,$A19,BD_REVIT!$F:$F,I$4) -> 19.65 | J19: =SUMIFS(BD_REVIT!$H:$H,BD_REVIT!$C:$C,$A19,BD_REVIT!$F:$F,J$4) -> 6.17 | K19: =SUMIFS(BD_REVIT!$H:$H,BD_REVIT!$C:$C,$A19,BD_REVIT!$F:$F,K$4) -> 6.4 | ... Y19: =SUMIFS(BD_REVIT!$H:$H,BD_REVIT!$C:$C,$A19,BD_REVIT!$F:$F,Y$4) -> 0 | Z19: =SUM(D19:Y19) -> 199.54 | AA19: =NIVEL!D403 -> 199.54 | AB19: =ROUND(Z19-AA19,2) -> 0
A20: 7.13 | B20: Soporte pera 1" | C20: Un. | D20: =SUMIFS(BD_REVIT!$H:$H,BD_REVIT!$C:$C,$A20,BD_REVIT!$F:$F,D$4) -> 0 | E20: =SUMIFS(BD_REVIT!$H:$H,BD_REVIT!$C:$C,$A20,BD_REVIT!$F:$F,E$4) -> 0 | F20: =SUMIFS(BD_REVIT!$H:$H,BD_REVIT!$C:$C,$A20,BD_REVIT!$F:$F,F$4) -> 0 | G20: =SUMIFS(BD_REVIT!$H:$H,BD_REVIT!$C:$C,$A20,BD_REVIT!$F:$F,G$4) -> 0 | H20: =SUMIFS(BD_REVIT!$H:$H,BD_REVIT!$C:$C,$A20,BD_REVIT!$F:$F,H$4) -> 0 | I20: =SUMIFS(BD_REVIT!$H:$H,BD_REVIT!$C:$C,$A20,BD_REVIT!$F:$F,I$4) -> 0 | J20: =SUMIFS(BD_REVIT!$H:$H,BD_REVIT!$C:$C,$A20,BD_REVIT!$F:$F,J$4) -> 0 | K20: =SUMIFS(BD_REVIT!$H:$H,BD_REVIT!$C:$C,$A20,BD_REVIT!$F:$F,K$4) -> 0 | ... Y20: =SUMIFS(BD_REVIT!$H:$H,BD_REVIT!$C:$C,$A20,BD_REVIT!$F:$F,Y$4) -> 0 | Z20: =SUM(D20:Y20) -> 0 | AA20: =NIVEL!D404 -> 0 | AB20: =ROUND(Z20-AA20,2) -> 0
A21: 7.14 | B21: Soporte pera 1-1/2" | C21: Un. | D21: =SUMIFS(BD_REVIT!$H:$H,BD_REVIT!$C:$C,$A21,BD_REVIT!$F:$F,D$4) -> 0 | E21: =SUMIFS(BD_REVIT!$H:$H,BD_REVIT!$C:$C,$A21,BD_REVIT!$F:$F,E$4) -> 0 | F21: =SUMIFS(BD_REVIT!$H:$H,BD_REVIT!$C:$C,$A21,BD_REVIT!$F:$F,F$4) -> 89 | G21: =SUMIFS(BD_REVIT!$H:$H,BD_REVIT!$C:$C,$A21,BD_REVIT!$F:$F,G$4) -> 127 | H21: =SUMIFS(BD_REVIT!$H:$H,BD_REVIT!$C:$C,$A21,BD_REVIT!$F:$F,H$4) -> 120 | I21: =SUMIFS(BD_REVIT!$H:$H,BD_REVIT!$C:$C,$A21,BD_REVIT!$F:$F,I$4) -> 90 | J21: =SUMIFS(BD_REVIT!$H:$H,BD_REVIT!$C:$C,$A21,BD_REVIT!$F:$F,J$4) -> 0 | K21: =SUMIFS(BD_REVIT!$H:$H,BD_REVIT!$C:$C,$A21,BD_REVIT!$F:$F,K$4) -> 6 | ... Y21: =SUMIFS(BD_REVIT!$H:$H,BD_REVIT!$C:$C,$A21,BD_REVIT!$F:$F,Y$4) -> 0 | Z21: =SUM(D21:Y21) -> 601 | AA21: =NIVEL!D405 -> 601 | AB21: =ROUND(Z21-AA21,2) -> 0
A22: 7.105 | B22: Soporte pera 2" | C22: Un. | D22: =SUMIFS(BD_REVIT!$H:$H,BD_REVIT!$C:$C,$A22,BD_REVIT!$F:$F,D$4) -> 0 | E22: =SUMIFS(BD_REVIT!$H:$H,BD_REVIT!$C:$C,$A22,BD_REVIT!$F:$F,E$4) -> 0 | F22: =SUMIFS(BD_REVIT!$H:$H,BD_REVIT!$C:$C,$A22,BD_REVIT!$F:$F,F$4) -> 0 | G22: =SUMIFS(BD_REVIT!$H:$H,BD_REVIT!$C:$C,$A22,BD_REVIT!$F:$F,G$4) -> 0 | H22: =SUMIFS(BD_REVIT!$H:$H,BD_REVIT!$C:$C,$A22,BD_REVIT!$F:$F,H$4) -> 0 | I22: =SUMIFS(BD_REVIT!$H:$H,BD_REVIT!$C:$C,$A22,BD_REVIT!$F:$F,I$4) -> 0 | J22: =SUMIFS(BD_REVIT!$H:$H,BD_REVIT!$C:$C,$A22,BD_REVIT!$F:$F,J$4) -> 53 | K22: =SUMIFS(BD_REVIT!$H:$H,BD_REVIT!$C:$C,$A22,BD_REVIT!$F:$F,K$4) -> 27 | ... Y22: =SUMIFS(BD_REVIT!$H:$H,BD_REVIT!$C:$C,$A22,BD_REVIT!$F:$F,Y$4) -> 0 | Z22: =SUM(D22:Y22) -> 80 | AA22: =NIVEL!D406 -> 80 | AB22: =ROUND(Z22-AA22,2) -> 0
A23: 7.15 | B23: Soporte pera 2-1/2" | C23: Un. | D23: =SUMIFS(BD_REVIT!$H:$H,BD_REVIT!$C:$C,$A23,BD_REVIT!$F:$F,D$4) -> 0 | E23: =SUMIFS(BD_REVIT!$H:$H,BD_REVIT!$C:$C,$A23,BD_REVIT!$F:$F,E$4) -> 0 | F23: =SUMIFS(BD_REVIT!$H:$H,BD_REVIT!$C:$C,$A23,BD_REVIT!$F:$F,F$4) -> 0 | G23: =SUMIFS(BD_REVIT!$H:$H,BD_REVIT!$C:$C,$A23,BD_REVIT!$F:$F,G$4) -> 0 | H23: =SUMIFS(BD_REVIT!$H:$H,BD_REVIT!$C:$C,$A23,BD_REVIT!$F:$F,H$4) -> 0 | I23: =SUMIFS(BD_REVIT!$H:$H,BD_REVIT!$C:$C,$A23,BD_REVIT!$F:$F,I$4) -> 0 | J23: =SUMIFS(BD_REVIT!$H:$H,BD_REVIT!$C:$C,$A23,BD_REVIT!$F:$F,J$4) -> 2 | K23: =SUMIFS(BD_REVIT!$H:$H,BD_REVIT!$C:$C,$A23,BD_REVIT!$F:$F,K$4) -> 0 | ... Y23: =SUMIFS(BD_REVIT!$H:$H,BD_REVIT!$C:$C,$A23,BD_REVIT!$F:$F,Y$4) -> 0 | Z23: =SUM(D23:Y23) -> 2 | AA23: =NIVEL!D407 -> 2 | AB23: =ROUND(Z23-AA23,2) -> 0
... A27: 7.19 | B27: Pasante en muro contencion 6" | C27: Un. | D27: =SUMIFS(BD_REVIT!$H:$H,BD_REVIT!$C:$C,$A27,BD_REVIT!$F:$F,D$4) -> 2 | E27: =SUMIFS(BD_REVIT!$H:$H,BD_REVIT!$C:$C,$A27,BD_REVIT!$F:$F,E$4) -> 0 | F27: =SUMIFS(BD_REVIT!$H:$H,BD_REVIT!$C:$C,$A27,BD_REVIT!$F:$F,F$4) -> 0 | G27: =SUMIFS(BD_REVIT!$H:$H,BD_REVIT!$C:$C,$A27,BD_REVIT!$F:$F,G$4) -> 0 | H27: =SUMIFS(BD_REVIT!$H:$H,BD_REVIT!$C:$C,$A27,BD_REVIT!$F:$F,H$4) -> 0 | I27: =SUMIFS(BD_REVIT!$H:$H,BD_REVIT!$C:$C,$A27,BD_REVIT!$F:$F,I$4) -> 0 | J27: =SUMIFS(BD_REVIT!$H:$H,BD_REVIT!$C:$C,$A27,BD_REVIT!$F:$F,J$4) -> 0 | K27: =SUMIFS(BD_REVIT!$H:$H,BD_REVIT!$C:$C,$A27,BD_REVIT!$F:$F,K$4) -> 0 | ... Y27: =SUMIFS(BD_REVIT!$H:$H,BD_REVIT!$C:$C,$A27,BD_REVIT!$F:$F,Y$4) -> 0 | Z27: =SUM(D27:Y27) -> 2 | AA27: =NIVEL!D411 -> 2 | AB27: =ROUND(Z27-AA27,2) -> 0
A28: 7.20 | B28: Soporte Antisísmico Longitudinal ø2-1/2" | C28: Un. | D28: =SUMIFS(BD_REVIT!$H:$H,BD_REVIT!$C:$C,$A28,BD_REVIT!$F:$F,D$4) -> 0 | E28: =SUMIFS(BD_REVIT!$H:$H,BD_REVIT!$C:$C,$A28,BD_REVIT!$F:$F,E$4) -> 0 | F28: =SUMIFS(BD_REVIT!$H:$H,BD_REVIT!$C:$C,$A28,BD_REVIT!$F:$F,F$4) -> 0 | G28: =SUMIFS(BD_REVIT!$H:$H,BD_REVIT!$C:$C,$A28,BD_REVIT!$F:$F,G$4) -> 0 | H28: =SUMIFS(BD_REVIT!$H:$H,BD_REVIT!$C:$C,$A28,BD_REVIT!$F:$F,H$4) -> 0 | I28: =SUMIFS(BD_REVIT!$H:$H,BD_REVIT!$C:$C,$A28,BD_REVIT!$F:$F,I$4) -> 0 | J28: =SUMIFS(BD_REVIT!$H:$H,BD_REVIT!$C:$C,$A28,BD_REVIT!$F:$F,J$4) -> 0 | K28: =SUMIFS(BD_REVIT!$H:$H,BD_REVIT!$C:$C,$A28,BD_REVIT!$F:$F,K$4) -> 0 | ... Y28: =SUMIFS(BD_REVIT!$H:$H,BD_REVIT!$C:$C,$A28,BD_REVIT!$F:$F,Y$4) -> 0 | Z28: =SUM(D28:Y28) -> 0 | AA28: =NIVEL!D413 -> 0 | AB28: =ROUND(Z28-AA28,2) -> 0
A29: 7.21 | B29: Soporte Antisísmico Transversal ø2-1/2" | C29: Un. | D29: =SUMIFS(BD_REVIT!$H:$H,BD_REVIT!$C:$C,$A29,BD_REVIT!$F:$F,D$4) -> 0 | E29: =SUMIFS(BD_REVIT!$H:$H,BD_REVIT!$C:$C,$A29,BD_REVIT!$F:$F,E$4) -> 0 | F29: =SUMIFS(BD_REVIT!$H:$H,BD_REVIT!$C:$C,$A29,BD_REVIT!$F:$F,F$4) -> 0 | G29: =SUMIFS(BD_REVIT!$H:$H,BD_REVIT!$C:$C,$A29,BD_REVIT!$F:$F,G$4) -> 0 | H29: =SUMIFS(BD_REVIT!$H:$H,BD_REVIT!$C:$C,$A29,BD_REVIT!$F:$F,H$4) -> 0 | I29: =SUMIFS(BD_REVIT!$H:$H,BD_REVIT!$C:$C,$A29,BD_REVIT!$F:$F,I$4) -> 0 | J29: =SUMIFS(BD_REVIT!$H:$H,BD_REVIT!$C:$C,$A29,BD_REVIT!$F:$F,J$4) -> 0 | K29: =SUMIFS(BD_REVIT!$H:$H,BD_REVIT!$C:$C,$A29,BD_REVIT!$F:$F,K$4) -> 2 | ... Y29: =SUMIFS(BD_REVIT!$H:$H,BD_REVIT!$C:$C,$A29,BD_REVIT!$F:$F,Y$4) -> 0 | Z29: =SUM(D29:Y29) -> 2 | AA29: =NIVEL!D414 -> 2 | AB29: =ROUND(Z29-AA29,2) -> 0
A30: 7.106 | B30: Soporte Antisísmico Longitudinal ø3" | C30: Un. | D30: =SUMIFS(BD_REVIT!$H:$H,BD_REVIT!$C:$C,$A30,BD_REVIT!$F:$F,D$4) -> 0 | E30: =SUMIFS(BD_REVIT!$H:$H,BD_REVIT!$C:$C,$A30,BD_REVIT!$F:$F,E$4) -> 2 | F30: =SUMIFS(BD_REVIT!$H:$H,BD_REVIT!$C:$C,$A30,BD_REVIT!$F:$F,F$4) -> 13 | G30: =SUMIFS(BD_REVIT!$H:$H,BD_REVIT!$C:$C,$A30,BD_REVIT!$F:$F,G$4) -> 11 | H30: =SUMIFS(BD_REVIT!$H:$H,BD_REVIT!$C:$C,$A30,BD_REVIT!$F:$F,H$4) -> 14 | I30: =SUMIFS(BD_REVIT!$H:$H,BD_REVIT!$C:$C,$A30,BD_REVIT!$F:$F,I$4) -> 15 | J30: =SUMIFS(BD_REVIT!$H:$H,BD_REVIT!$C:$C,$A30,BD_REVIT!$F:$F,J$4) -> 3 | K30: =SUMIFS(BD_REVIT!$H:$H,BD_REVIT!$C:$C,$A30,BD_REVIT!$F:$F,K$4) -> 2 | ... Y30: =SUMIFS(BD_REVIT!$H:$H,BD_REVIT!$C:$C,$A30,BD_REVIT!$F:$F,Y$4) -> 0 | Z30: =SUM(D30:Y30) -> 60 | AA30: =NIVEL!D415 -> 60 | AB30: =ROUND(Z30-AA30,2) -> 0
A31: 7.107 | B31: Soporte Antisísmico Transversal ø3" | C31: Un. | D31: =SUMIFS(BD_REVIT!$H:$H,BD_REVIT!$C:$C,$A31,BD_REVIT!$F:$F,D$4) -> 0 | E31: =SUMIFS(BD_REVIT!$H:$H,BD_REVIT!$C:$C,$A31,BD_REVIT!$F:$F,E$4) -> 3 | F31: =SUMIFS(BD_REVIT!$H:$H,BD_REVIT!$C:$C,$A31,BD_REVIT!$F:$F,F$4) -> 38 | G31: =SUMIFS(BD_REVIT!$H:$H,BD_REVIT!$C:$C,$A31,BD_REVIT!$F:$F,G$4) -> 35 | H31: =SUMIFS(BD_REVIT!$H:$H,BD_REVIT!$C:$C,$A31,BD_REVIT!$F:$F,H$4) -> 31 | I31: =SUMIFS(BD_REVIT!$H:$H,BD_REVIT!$C:$C,$A31,BD_REVIT!$F:$F,I$4) -> 38 | J31: =SUMIFS(BD_REVIT!$H:$H,BD_REVIT!$C:$C,$A31,BD_REVIT!$F:$F,J$4) -> 16 | K31: =SUMIFS(BD_REVIT!$H:$H,BD_REVIT!$C:$C,$A31,BD_REVIT!$F:$F,K$4) -> 6 | ... Y31: =SUMIFS(BD_REVIT!$H:$H,BD_REVIT!$C:$C,$A31,BD_REVIT!$F:$F,Y$4) -> 0 | Z31: =SUM(D31:Y31) -> 167 | AA31: =NIVEL!D416 -> 167 | AB31: =ROUND(Z31-AA31,2) -> 0
A32: 7.108 | B32: Soporte Antisísmico Longitudinal ø4" | C32: Un. | D32: =SUMIFS(BD_REVIT!$H:$H,BD_REVIT!$C:$C,$A32,BD_REVIT!$F:$F,D$4) -> 0 | E32: =SUMIFS(BD_REVIT!$H:$H,BD_REVIT!$C:$C,$A32,BD_REVIT!$F:$F,E$4) -> 0 | F32: =SUMIFS(BD_REVIT!$H:$H,BD_REVIT!$C:$C,$A32,BD_REVIT!$F:$F,F$4) -> 0 | G32: =SUMIFS(BD_REVIT!$H:$H,BD_REVIT!$C:$C,$A32,BD_REVIT!$F:$F,G$4) -> 0 | H32: =SUMIFS(BD_REVIT!$H:$H,BD_REVIT!$C:$C,$A32,BD_REVIT!$F:$F,H$4) -> 0 | I32: =SUMIFS(BD_REVIT!$H:$H,BD_REVIT!$C:$C,$A32,BD_REVIT!$F:$F,I$4) -> 0 | J32: =SUMIFS(BD_REVIT!$H:$H,BD_REVIT!$C:$C,$A32,BD_REVIT!$F:$F,J$4) -> 1 | K32: =SUMIFS(BD_REVIT!$H:$H,BD_REVIT!$C:$C,$A32,BD_REVIT!$F:$F,K$4) -> 0 | ... Y32: =SUMIFS(BD_REVIT!$H:$H,BD_REVIT!$C:$C,$A32,BD_REVIT!$F:$F,Y$4) -> 0 | Z32: =SUM(D32:Y32) -> 1 | AA32: =NIVEL!D417 -> 1 | AB32: =ROUND(Z32-AA32,2) -> 0
A33: 7.109 | B33: Soporte Antisísmico Transversal ø4" | C33: Un. | D33: =SUMIFS(BD_REVIT!$H:$H,BD_REVIT!$C:$C,$A33,BD_REVIT!$F:$F,D$4) -> 0 | E33: =SUMIFS(BD_REVIT!$H:$H,BD_REVIT!$C:$C,$A33,BD_REVIT!$F:$F,E$4) -> 0 | F33: =SUMIFS(BD_REVIT!$H:$H,BD_REVIT!$C:$C,$A33,BD_REVIT!$F:$F,F$4) -> 0 | G33: =SUMIFS(BD_REVIT!$H:$H,BD_REVIT!$C:$C,$A33,BD_REVIT!$F:$F,G$4) -> 0 | H33: =SUMIFS(BD_REVIT!$H:$H,BD_REVIT!$C:$C,$A33,BD_REVIT!$F:$F,H$4) -> 0 | I33: =SUMIFS(BD_REVIT!$H:$H,BD_REVIT!$C:$C,$A33,BD_REVIT!$F:$F,I$4) -> 0 | J33: =SUMIFS(BD_REVIT!$H:$H,BD_REVIT!$C:$C,$A33,BD_REVIT!$F:$F,J$4) -> 3 | K33: =SUMIFS(BD_REVIT!$H:$H,BD_REVIT!$C:$C,$A33,BD_REVIT!$F:$F,K$4) -> 0 | ... Y33: =SUMIFS(BD_REVIT!$H:$H,BD_REVIT!$C:$C,$A33,BD_REVIT!$F:$F,Y$4) -> 0 | Z33: =SUM(D33:Y33) -> 3 | AA33: =NIVEL!D418 -> 3 | AB33: =ROUND(Z33-AA33,2) -> 0
A34: 7.22 | B34: Soporte Antisísmico Longitudinal ø6" | C34: Un. | D34: =SUMIFS(BD_REVIT!$H:$H,BD_REVIT!$C:$C,$A34,BD_REVIT!$F:$F,D$4) -> 6 | E34: =SUMIFS(BD_REVIT!$H:$H,BD_REVIT!$C:$C,$A34,BD_REVIT!$F:$F,E$4) -> 0 | F34: =SUMIFS(BD_REVIT!$H:$H,BD_REVIT!$C:$C,$A34,BD_REVIT!$F:$F,F$4) -> 3 | G34: =SUMIFS(BD_REVIT!$H:$H,BD_REVIT!$C:$C,$A34,BD_REVIT!$F:$F,G$4) -> 2 | H34: =SUMIFS(BD_REVIT!$H:$H,BD_REVIT!$C:$C,$A34,BD_REVIT!$F:$F,H$4) -> 0 | I34: =SUMIFS(BD_REVIT!$H:$H,BD_REVIT!$C:$C,$A34,BD_REVIT!$F:$F,I$4) -> 1 | J34: =SUMIFS(BD_REVIT!$H:$H,BD_REVIT!$C:$C,$A34,BD_REVIT!$F:$F,J$4) -> 0 | K34: =SUMIFS(BD_REVIT!$H:$H,BD_REVIT!$C:$C,$A34,BD_REVIT!$F:$F,K$4) -> 0 | ... Y34: =SUMIFS(BD_REVIT!$H:$H,BD_REVIT!$C:$C,$A34,BD_REVIT!$F:$F,Y$4) -> 0 | Z34: =SUM(D34:Y34) -> 14 | AA34: =NIVEL!D419 -> 14 | AB34: =ROUND(Z34-AA34,2) -> 0
A35: 7.23 | B35: Soporte Antisísmico Transversal ø6" | C35: Un. | D35: =SUMIFS(BD_REVIT!$H:$H,BD_REVIT!$C:$C,$A35,BD_REVIT!$F:$F,D$4) -> 9 | E35: =SUMIFS(BD_REVIT!$H:$H,BD_REVIT!$C:$C,$A35,BD_REVIT!$F:$F,E$4) -> 0 | F35: =SUMIFS(BD_REVIT!$H:$H,BD_REVIT!$C:$C,$A35,BD_REVIT!$F:$F,F$4) -> 0 | G35: =SUMIFS(BD_REVIT!$H:$H,BD_REVIT!$C:$C,$A35,BD_REVIT!$F:$F,G$4) -> 2 | H35: =SUMIFS(BD_REVIT!$H:$H,BD_REVIT!$C:$C,$A35,BD_REVIT!$F:$F,H$4) -> 0 | I35: =SUMIFS(BD_REVIT!$H:$H,BD_REVIT!$C:$C,$A35,BD_REVIT!$F:$F,I$4) -> 2 | J35: =SUMIFS(BD_REVIT!$H:$H,BD_REVIT!$C:$C,$A35,BD_REVIT!$F:$F,J$4) -> 2 | K35: =SUMIFS(BD_REVIT!$H:$H,BD_REVIT!$C:$C,$A35,BD_REVIT!$F:$F,K$4) -> 0 | ... Y35: =SUMIFS(BD_REVIT!$H:$H,BD_REVIT!$C:$C,$A35,BD_REVIT!$F:$F,Y$4) -> 0 | Z35: =SUM(D35:Y35) -> 21 | AA35: =NIVEL!D420 -> 21 | AB35: =ROUND(Z35-AA35,2) -> 0
A36: 7.24 | B36: Tubería A.C. Sche 10 De ø6" | C36: Ml. | D36: =SUMIFS(BD_REVIT!$H:$H,BD_REVIT!$C:$C,$A36,BD_REVIT!$F:$F,D$4) -> 0 | E36: =SUMIFS(BD_REVIT!$H:$H,BD_REVIT!$C:$C,$A36,BD_REVIT!$F:$F,E$4) -> 0 | F36: =SUMIFS(BD_REVIT!$H:$H,BD_REVIT!$C:$C,$A36,BD_REVIT!$F:$F,F$4) -> 0 | G36: =SUMIFS(BD_REVIT!$H:$H,BD_REVIT!$C:$C,$A36,BD_REVIT!$F:$F,G$4) -> 0 | H36: =SUMIFS(BD_REVIT!$H:$H,BD_REVIT!$C:$C,$A36,BD_REVIT!$F:$F,H$4) -> 0 | I36: =SUMIFS(BD_REVIT!$H:$H,BD_REVIT!$C:$C,$A36,BD_REVIT!$F:$F,I$4) -> 0 | J36: =SUMIFS(BD_REVIT!$H:$H,BD_REVIT!$C:$C,$A36,BD_REVIT!$F:$F,J$4) -> 0 | K36: =SUMIFS(BD_REVIT!$H:$H,BD_REVIT!$C:$C,$A36,BD_REVIT!$F:$F,K$4) -> 0 | ... Y36: =SUMIFS(BD_REVIT!$H:$H,BD_REVIT!$C:$C,$A36,BD_REVIT!$F:$F,Y$4) -> 0 | Z36: =SUM(D36:Y36) -> 0 | AA36: =NIVEL!D422 -> 0 | AB36: =ROUND(Z36-AA36,2) -> 0
A37: 7.25 | B37: Soporte riel chanel 6" | C37: Un. | D37: =SUMIFS(BD_REVIT!$H:$H,BD_REVIT!$C:$C,$A37,BD_REVIT!$F:$F,D$4) -> 0 | E37: =SUMIFS(BD_REVIT!$H:$H,BD_REVIT!$C:$C,$A37,BD_REVIT!$F:$F,E$4) -> 0 | F37: =SUMIFS(BD_REVIT!$H:$H,BD_REVIT!$C:$C,$A37,BD_REVIT!$F:$F,F$4) -> 0 | G37: =SUMIFS(BD_REVIT!$H:$H,BD_REVIT!$C:$C,$A37,BD_REVIT!$F:$F,G$4) -> 0 | H37: =SUMIFS(BD_REVIT!$H:$H,BD_REVIT!$C:$C,$A37,BD_REVIT!$F:$F,H$4) -> 0 | I37: =SUMIFS(BD_REVIT!$H:$H,BD_REVIT!$C:$C,$A37,BD_REVIT!$F:$F,I$4) -> 0 | J37: =SUMIFS(BD_REVIT!$H:$H,BD_REVIT!$C:$C,$A37,BD_REVIT!$F:$F,J$4) -> 0 | K37: =SUMIFS(BD_REVIT!$H:$H,BD_REVIT!$C:$C,$A37,BD_REVIT!$F:$F,K$4) -> 0 | ... Y37: =SUMIFS(BD_REVIT!$H:$H,BD_REVIT!$C:$C,$A37,BD_REVIT!$F:$F,Y$4) -> 0 | Z37: =SUM(D37:Y37) -> 0 | AA37: =NIVEL!D423 -> 0 | AB37: =ROUND(Z37-AA37,2) -> 0
A38: 7.26 | B38: Pasantes en placa ø6" (sacanucleos) | C38: Un. | D38: =SUMIFS(BD_REVIT!$H:$H,BD_REVIT!$C:$C,$A38,BD_REVIT!$F:$F,D$4) -> 0 | E38: =SUMIFS(BD_REVIT!$H:$H,BD_REVIT!$C:$C,$A38,BD_REVIT!$F:$F,E$4) -> 0 | F38: =SUMIFS(BD_REVIT!$H:$H,BD_REVIT!$C:$C,$A38,BD_REVIT!$F:$F,F$4) -> 0 | G38: =SUMIFS(BD_REVIT!$H:$H,BD_REVIT!$C:$C,$A38,BD_REVIT!$F:$F,G$4) -> 0 | H38: =SUMIFS(BD_REVIT!$H:$H,BD_REVIT!$C:$C,$A38,BD_REVIT!$F:$F,H$4) -> 0 | I38: =SUMIFS(BD_REVIT!$H:$H,BD_REVIT!$C:$C,$A38,BD_REVIT!$F:$F,I$4) -> 0 | J38: =SUMIFS(BD_REVIT!$H:$H,BD_REVIT!$C:$C,$A38,BD_REVIT!$F:$F,J$4) -> 0 | K38: =SUMIFS(BD_REVIT!$H:$H,BD_REVIT!$C:$C,$A38,BD_REVIT!$F:$F,K$4) -> 0 | ... Y38: =SUMIFS(BD_REVIT!$H:$H,BD_REVIT!$C:$C,$A38,BD_REVIT!$F:$F,Y$4) -> 0 | Z38: =SUM(D38:Y38) -> 0 | AA38: =NIVEL!D424 -> 0 | AB38: =ROUND(Z38-AA38,2) -> 0
A39: 7.27 | B39: Sello intumescente 2-1/2 | C39: Un. | D39: =SUMIFS(BD_REVIT!$H:$H,BD_REVIT!$C:$C,$A39,BD_REVIT!$F:$F,D$4) -> 0 | E39: =SUMIFS(BD_REVIT!$H:$H,BD_REVIT!$C:$C,$A39,BD_REVIT!$F:$F,E$4) -> 0 | F39: =SUMIFS(BD_REVIT!$H:$H,BD_REVIT!$C:$C,$A39,BD_REVIT!$F:$F,F$4) -> 0 | G39: =SUMIFS(BD_REVIT!$H:$H,BD_REVIT!$C:$C,$A39,BD_REVIT!$F:$F,G$4) -> 0 | H39: =SUMIFS(BD_REVIT!$H:$H,BD_REVIT!$C:$C,$A39,BD_REVIT!$F:$F,H$4) -> 0 | I39: =SUMIFS(BD_REVIT!$H:$H,BD_REVIT!$C:$C,$A39,BD_REVIT!$F:$F,I$4) -> 0 | J39: =SUMIFS(BD_REVIT!$H:$H,BD_REVIT!$C:$C,$A39,BD_REVIT!$F:$F,J$4) -> 0 | K39: =SUMIFS(BD_REVIT!$H:$H,BD_REVIT!$C:$C,$A39,BD_REVIT!$F:$F,K$4) -> 0 | ... Y39: =SUMIFS(BD_REVIT!$H:$H,BD_REVIT!$C:$C,$A39,BD_REVIT!$F:$F,Y$4) -> 0 | Z39: =SUM(D39:Y39) -> 0 | AA39: =NIVEL!D425 -> 0 | AB39: =ROUND(Z39-AA39,2) -> 0
A40: 7.110 | B40: Sello intumescente 1-1/2" | C40: Un. | D40: =SUMIFS(BD_REVIT!$H:$H,BD_REVIT!$C:$C,$A40,BD_REVIT!$F:$F,D$4) -> 0 | E40: =SUMIFS(BD_REVIT!$H:$H,BD_REVIT!$C:$C,$A40,BD_REVIT!$F:$F,E$4) -> 0 | F40: =SUMIFS(BD_REVIT!$H:$H,BD_REVIT!$C:$C,$A40,BD_REVIT!$F:$F,F$4) -> 0 | G40: =SUMIFS(BD_REVIT!$H:$H,BD_REVIT!$C:$C,$A40,BD_REVIT!$F:$F,G$4) -> 0 | H40: =SUMIFS(BD_REVIT!$H:$H,BD_REVIT!$C:$C,$A40,BD_REVIT!$F:$F,H$4) -> 0 | I40: =SUMIFS(BD_REVIT!$H:$H,BD_REVIT!$C:$C,$A40,BD_REVIT!$F:$F,I$4) -> 0 | J40: =SUMIFS(BD_REVIT!$H:$H,BD_REVIT!$C:$C,$A40,BD_REVIT!$F:$F,J$4) -> 0 | K40: =SUMIFS(BD_REVIT!$H:$H,BD_REVIT!$C:$C,$A40,BD_REVIT!$F:$F,K$4) -> 2 | ... Y40: =SUMIFS(BD_REVIT!$H:$H,BD_REVIT!$C:$C,$A40,BD_REVIT!$F:$F,Y$4) -> 0 | Z40: =SUM(D40:Y40) -> 26 | AA40: =NIVEL!D426 -> 26 | AB40: =ROUND(Z40-AA40,2) -> 0
A41: 7.111 | B41: Sello intumescente 4" | C41: Un. | D41: =SUMIFS(BD_REVIT!$H:$H,BD_REVIT!$C:$C,$A41,BD_REVIT!$F:$F,D$4) -> 0 | E41: =SUMIFS(BD_REVIT!$H:$H,BD_REVIT!$C:$C,$A41,BD_REVIT!$F:$F,E$4) -> 0 | F41: =SUMIFS(BD_REVIT!$H:$H,BD_REVIT!$C:$C,$A41,BD_REVIT!$F:$F,F$4) -> 0 | G41: =SUMIFS(BD_REVIT!$H:$H,BD_REVIT!$C:$C,$A41,BD_REVIT!$F:$F,G$4) -> 0 | H41: =SUMIFS(BD_REVIT!$H:$H,BD_REVIT!$C:$C,$A41,BD_REVIT!$F:$F,H$4) -> 0 | I41: =SUMIFS(BD_REVIT!$H:$H,BD_REVIT!$C:$C,$A41,BD_REVIT!$F:$F,I$4) -> 0 | J41: =SUMIFS(BD_REVIT!$H:$H,BD_REVIT!$C:$C,$A41,BD_REVIT!$F:$F,J$4) -> 1 | K41: =SUMIFS(BD_REVIT!$H:$H,BD_REVIT!$C:$C,$A41,BD_REVIT!$F:$F,K$4) -> 0 | ... Y41: =SUMIFS(BD_REVIT!$H:$H,BD_REVIT!$C:$C,$A41,BD_REVIT!$F:$F,Y$4) -> 0 | Z41: =SUM(D41:Y41) -> 1 | AA41: =NIVEL!D427 -> 1 | AB41: =ROUND(Z41-AA41,2) -> 0
A42: 7.28 | B42: Tubería A.C. Sche 10 De ø6" (Descolgada) | C42: Ml. | D42: =SUMIFS(BD_REVIT!$H:$H,BD_REVIT!$C:$C,$A42,BD_REVIT!$F:$F,D$4) -> 0 | E42: =SUMIFS(BD_REVIT!$H:$H,BD_REVIT!$C:$C,$A42,BD_REVIT!$F:$F,E$4) -> 0 | F42: =SUMIFS(BD_REVIT!$H:$H,BD_REVIT!$C:$C,$A42,BD_REVIT!$F:$F,F$4) -> 0 | G42: =SUMIFS(BD_REVIT!$H:$H,BD_REVIT!$C:$C,$A42,BD_REVIT!$F:$F,G$4) -> 0 | H42: =SUMIFS(BD_REVIT!$H:$H,BD_REVIT!$C:$C,$A42,BD_REVIT!$F:$F,H$4) -> 0 | I42: =SUMIFS(BD_REVIT!$H:$H,BD_REVIT!$C:$C,$A42,BD_REVIT!$F:$F,I$4) -> 0 | J42: =SUMIFS(BD_REVIT!$H:$H,BD_REVIT!$C:$C,$A42,BD_REVIT!$F:$F,J$4) -> 0 | K42: =SUMIFS(BD_REVIT!$H:$H,BD_REVIT!$C:$C,$A42,BD_REVIT!$F:$F,K$4) -> 0 | ... Y42: =SUMIFS(BD_REVIT!$H:$H,BD_REVIT!$C:$C,$A42,BD_REVIT!$F:$F,Y$4) -> 0 | Z42: =SUM(D42:Y42) -> 0 | AA42: =NIVEL!D429 -> 0 | AB42: =ROUND(Z42-AA42,2) -> 0
A43: 7.29 | B43: Soporte Antisísmico Cuatro vías ø6" | C43: Un. | D43: =SUMIFS(BD_REVIT!$H:$H,BD_REVIT!$C:$C,$A43,BD_REVIT!$F:$F,D$4) -> 0 | E43: =SUMIFS(BD_REVIT!$H:$H,BD_REVIT!$C:$C,$A43,BD_REVIT!$F:$F,E$4) -> 0 | F43: =SUMIFS(BD_REVIT!$H:$H,BD_REVIT!$C:$C,$A43,BD_REVIT!$F:$F,F$4) -> 0 | G43: =SUMIFS(BD_REVIT!$H:$H,BD_REVIT!$C:$C,$A43,BD_REVIT!$F:$F,G$4) -> 0 | H43: =SUMIFS(BD_REVIT!$H:$H,BD_REVIT!$C:$C,$A43,BD_REVIT!$F:$F,H$4) -> 0 | I43: =SUMIFS(BD_REVIT!$H:$H,BD_REVIT!$C:$C,$A43,BD_REVIT!$F:$F,I$4) -> 0 | J43: =SUMIFS(BD_REVIT!$H:$H,BD_REVIT!$C:$C,$A43,BD_REVIT!$F:$F,J$4) -> 0 | K43: =SUMIFS(BD_REVIT!$H:$H,BD_REVIT!$C:$C,$A43,BD_REVIT!$F:$F,K$4) -> 0 | ... Y43: =SUMIFS(BD_REVIT!$H:$H,BD_REVIT!$C:$C,$A43,BD_REVIT!$F:$F,Y$4) -> 0 | Z43: =SUM(D43:Y43) -> 0 | AA43: =NIVEL!D431 -> 0 | AB43: =ROUND(Z43-AA43,2) -> 0
...

Sheet LISTAS
A1: Código | B1: Descripción | C1: Und. | D1: Nivel de piso
A2: 7.01 | B2: Puntos Conexión Valvula Angular 2-1/2 | C2: Un. | D2: Nivel Cuarto de Bomba Sub
A3: 7.02 | B3: Puntos AC 1-1/2" Gabinetes Tipo 2 | C3: Un. | D3: Nivel Sótano 4
A4: 7.03 | B4: Puntos Sprinkler - AC 1" | C4: Un. | D4: Nivel Sótano 3
A5: 7.04 | B5: Suministro y Conexión Gabinete tipo 2 en Lamina Cold Rolled Calibre 20 de 0.77×0.77×0.22, Válvula angular 1½" Regulada, Soporte tipo canasta, Manguera fibra poliester y caucho 1½"×100', Boquilla chorro y niebla 1½"-Hacha pico 4½" lbs, Llave Spaner-Extintor de polvo | C5: Un. | D5: Nivel Sótano 2
A6: 7.05 | B6: Rociador Sprinkler ø1/2" K=5,6 estándar QR | C6: Un. | D6: Nivel Sótano 1
A7: 7.06 | B7: Rociador Sprinkler ø1/2" K=11,2 extendida QR | C7: Un. | D7: Nivel Semisótano
A8: 7.07 | B8: Tubería A.C. Sche 10 De ø1" | C8: Ml. | D8: Nivel 1
A9: 7.103 | B9: Tubería A.C. Sche 10 De ø1 1/4" | C9: Ml. | D9: Nivel 2
A10: 7.08 | B10: Tubería A.C. Sche 10 De ø1 1/2" | C10: Ml. | D10: Nivel 3
A11: 7.104 | B11: Tubería A.C. Sche 10 De ø2" | C11: Ml. | D11: Nivel 4
A12: 7.09 | B12: Tubería A.C. Sche 10 De ø2 1/2" | C12: Ml. | D12: Nivel 5
... A22: 7.18 | B22: Soporte pera 6" | C22: Un. | D22: Nivel 15
A23: 7.19 | B23: Pasante en muro contencion 6" | C23: Un.
A24: 7.20 | B24: Soporte Antisísmico Longitudinal ø2-1/2" | C24: Un.
A25: 7.21 | B25: Soporte Antisísmico Transversal ø2-1/2" | C25: Un.
A26: 7.106 | B26: Soporte Antisísmico Longitudinal ø3" | C26: Un.
A27: 7.107 | B27: Soporte Antisísmico Transversal ø3" | C27: Un.
A28: 7.108 | B28: Soporte Antisísmico Longitudinal ø4" | C28: Un.
A29: 7.109 | B29: Soporte Antisísmico Transversal ø4" | C29: Un.
A30: 7.22 | B30: Soporte Antisísmico Longitudinal ø6" | C30: Un.
A31: 7.23 | B31: Soporte Antisísmico Transversal ø6" | C31: Un.
A32: 7.24 | B32: Tubería A.C. Sche 10 De ø6" | C32: Ml.
A33: 7.25 | B33: Soporte riel chanel 6" | C33: Un.
A34: 7.26 | B34: Pasantes en placa ø6" (sacanucleos) | C34: Un.
... A118: 7.102 | B118: Suministro e instalacion de Linea de sensado. Incluye tuberia de cobre de ø1/2", accesorios de cobre, válvulas de cierre, cheques perforados, manómetros y soportería. (SE RECOMIENDA QUE LA INSTALACIÓN DE LA DE SENSADO SE HA REALIZADA POR EL MISMO PROVEEDOR DEL SUMINISTRO DE LA BOMBA P.PAL Y JOCKEY). | C118: Glb.
